Workbook

Sheet 종합
A1: * 금융업제외 | I1: 구분 | J1: EPS성장율 | K1: roe & pbr | L1: 야마구치 | M1: RIM(개별) | N1: RIM(연결) | O1: 무성장가치
E2: 입력F | F2: 삼성전자 | I2: value | J2: =VLOOKUP($F$2,종합!$B:T,9,FALSE) -> 1056148.8 | K2: =VLOOKUP($F$2,종합!$B:U,10,FALSE) -> 1411728.2 | L2: =VLOOKUP($F$2,종합!$B:U,11,FALSE) -> 2417621.9 | M2: =VLOOKUP($F$2,종합!$B:V,12,FALSE) -> 1383339.9 | N2: =VLOOKUP($F$2,종합!$B:W,13,FALSE) -> 2302459.9 | O2: =VLOOKUP($F$2,종합!$B:X,14,FALSE) -> 1493125.8
I3: 주가 | J3: =VLOOKUP($F$2,종합!$B:$I,8,FALSE) -> #N/A | K3: =J3 -> #N/A | L3: =K3 -> #N/A | M3: =L3 -> #N/A | N3: =M3 -> #N/A | O3: =N3 -> #N/A
A5: CODE | B5: 종목 | C5: 주재무 | D5: 실적 | E5: 시가총액 (억) | F5: PER | G5: PBR | H5: ROE | I5: 주가 (원) | J5: EPS성장율 (원) | K5: roe & pbr (원) | L5: 야마구치 (원) | M5: RIM(개별) (원) | N5: RIM(연결) (원) | O5: 무성장가치 (원) | P5: 업종 | Q5: 주식수 | R5: 순이익 | S5: 자본총계
A6: A005930 | B6: 삼성전자 | C6: 연결 | D6: 3Q | E6: =I6*Q6/100000000 -> #N/A | F6: =IFERROR(E6/R6,"-") -> - | G6: =IFERROR(E6/S6,"-") -> - | H6: =IFERROR(G6/F6,"-") -> - | I6: =VLOOKUP(B6,NAVER!$A$1:$G$1670,5,FALSE) -> #N/A | J6: =VLOOKUP(A6,'EPS 성장율'!A:L,COLUMN('EPS 성장율'!L7),FALSE) -> 1056148.8 | K6: =VLOOKUP($A6,'roe&pbr'!$A:$Q,COLUMN('roe&pbr'!J7),FALSE) -> 1411728.2 | L6: =IFERROR(VLOOKUP($A6,야마구치요헤이!$A:$K,COLUMN(야마구치요헤이!K7),FALSE),"-") -> 2417621.9 | M6: =IFERROR(VLOOKUP($A6,'RIM (개별)'!$A:$Y,COLUMN('RIM (개별)'!H11),FALSE),"-") -> 1383339.9 | N6: =IFERROR(VLOOKUP($A6,'RIM (연결)'!$A:$Y,COLUMN('RIM (연결)'!H9),FALSE),"-") -> 2302459.9 | O6: =IFERROR(VLOOKUP($A6,무성장가치!$A:$Q,COLUMN(무성장가치!J7),FALSE),"-") -> 1493125.8 | P6: 휴대폰 및 관련부품 | Q6: 140679337 | R6: 187409.41 | S6: 1732696.6
A7: A015760 | B7: 한국전력 | C7: 연결 | D7: 3Q | E7: =I7*Q7/100000000 -> 146367.81 | F7: =IFERROR(E7/R7,"-") -> 1.7572433 | G7: =IFERROR(E7/S7,"-") -> 0.20613511 | H7: =IFERROR(G7/F7,"-") -> 0.11730596 | I7: =IF(COUNTIF(현재가!$A:$A,$B7),VLOOKUP($B7,현재가!$A:$B,2,FALSE),VLOOKUP($B7,현재가!$D:$E,2,FALSE)) -> 22800 | J7: =VLOOKUP(A7,'EPS 성장율'!A:L,COLUMN('EPS 성장율'!L7),FALSE) -> 92115.73 | K7: =VLOOKUP($A7,'roe&pbr'!$A:$Q,COLUMN('roe&pbr'!J7),FALSE) -> 140972.46 | L7: =IFERROR(VLOOKUP($A7,야마구치요헤이!$A:$K,COLUMN(야마구치요헤이!K7),FALSE),"-") -> -19096.834 | M7: =IFERROR(VLOOKUP($A7,'RIM (개별)'!$A:$Y,COLUMN('RIM (개별)'!H11),FALSE),"-") -> 26896.942 | N7: =IFERROR(VLOOKUP($A7,'RIM (연결)'!$A:$Y,COLUMN('RIM (연결)'!H9),FALSE),"-") -> 48015.878 | O7: =IFERROR(VLOOKUP($A7,무성장가치!$A:$Q,COLUMN(무성장가치!J7),FALSE),"-") -> 157754.12 | P7: 전력 | Q7: 641964077 | R7: 83293.99 | S7: 710057.63
A8: A005380 | B8: 현대차 | C8: 연결 | D8: 3Q | E8: =I8*Q8/100000000 -> 451566.78 | F8: =IFERROR(E8/R8,"-") -> 7.4789359 | G8: =IFERROR(E8/S8,"-") -> 0.70267483 | H8: =IFERROR(G8/F8,"-") -> 0.093953851 | I8: =IF(COUNTIF(현재가!$A:$A,$B8),VLOOKUP($B8,현재가!$A:$B,2,FALSE),VLOOKUP($B8,현재가!$D:$E,2,FALSE)) -> 205000 | J8: =VLOOKUP(A8,'EPS 성장율'!A:L,COLUMN('EPS 성장율'!L8),FALSE) -> - | K8: =VLOOKUP($A8,'roe&pbr'!$A:$Q,COLUMN('roe&pbr'!J8),FALSE) -> 268781.88 | L8: =IFERROR(VLOOKUP($A8,야마구치요헤이!$A:$K,COLUMN(야마구치요헤이!K8),FALSE),"-") -> 39240.378 | M8: =IFERROR(VLOOKUP($A8,'RIM (개별)'!$A:$Y,COLUMN('RIM (개별)'!H12),FALSE),"-") -> 100464.17 | N8: =IFERROR(VLOOKUP($A8,'RIM (연결)'!$A:$Y,COLUMN('RIM (연결)'!H10),FALSE),"-") -> 107418.63 | O8: =IFERROR(VLOOKUP($A8,무성장가치!$A:$Q,COLUMN(무성장가치!J8),FALSE),"-") -> 83281.667 | P8: 자동차 | Q8: 220276479 | R8: 60378.48 | S8: 642639.76
A9: A028260 | B9: 삼성물산 | C9: 연결 | D9: 3Q | E9: =I9*Q9/100000000 -> 231421.85 | F9: =IFERROR(E9/R9,"-") -> -86.775022 | G9: =IFERROR(E9/S9,"-") -> 1.4060194 | H9: =IFERROR(G9/F9,"-") -> -0.016203043 | I9: =IF(COUNTIF(현재가!$A:$A,$B9),VLOOKUP($B9,현재가!$A:$B,2,FALSE),VLOOKUP($B9,현재가!$D:$E,2,FALSE)) -> 122000 | J9: =VLOOKUP(A9,'EPS 성장율'!A:L,COLUMN('EPS 성장율'!L9),FALSE) -> 15817.051 | K9: =VLOOKUP($A9,'roe&pbr'!$A:$Q,COLUMN('roe&pbr'!J9),FALSE) -> 115095.35 | L9: =IFERROR(VLOOKUP($A9,야마구치요헤이!$A:$K,COLUMN(야마구치요헤이!K9),FALSE),"-") -> 39520.057 | M9: =IFERROR(VLOOKUP($A9,'RIM (개별)'!$A:$Y,COLUMN('RIM (개별)'!H13),FALSE),"-") -> 39209.75 | N9: =IFERROR(VLOOKUP($A9,'RIM (연결)'!$A:$Y,COLUMN('RIM (연결)'!H11),FALSE),"-") -> 41669.353 | O9: =IFERROR(VLOOKUP($A9,무성장가치!$A:$Q,COLUMN(무성장가치!J9),FALSE),"-") -> 61341.083 | P9: 복합 산업 | Q9: 189690043 | R9: -2666.9178 | S9: 164593.64
A10: A035420 | B10: NAVER | C10: 연결 | D10: 3Q | E10: =I10*Q10/100000000 -> 128060.01 | F10: =IFERROR(E10/R10,"-") -> 17.923567 | G10: =IFERROR(E10/S10,"-") -> 3.4542231 | H10: =IFERROR(G10/F10,"-") -> 0.19271963 | I10: =IF(COUNTIF(현재가!$A:$A,$B10),VLOOKUP($B10,현재가!$A:$B,2,FALSE),VLOOKUP($B10,현재가!$D:$E,2,FALSE)) -> 388500 | J10: =VLOOKUP(A10,'EPS 성장율'!A:L,COLUMN('EPS 성장율'!L10),FALSE) -> 195745.7 | K10: =VLOOKUP($A10,'roe&pbr'!$A:$Q,COLUMN('roe&pbr'!J10),FALSE) -> 326732.78 | L10: =IFERROR(VLOOKUP($A10,야마구치요헤이!$A:$K,COLUMN(야마구치요헤이!K10),FALSE),"-") -> 293096.21 | M10: =IFERROR(VLOOKUP($A10,'RIM (개별)'!$A:$Y,COLUMN('RIM (개별)'!H14),FALSE),"-") -> 258555.68 | N10: =IFERROR(VLOOKUP($A10,'RIM (연결)'!$A:$Y,COLUMN('RIM (연결)'!H12),FALSE),"-") -> 432304.55 | O10: =IFERROR(VLOOKUP($A10,무성장가치!$A:$Q,COLUMN(무성장가치!J10),FALSE),"-") -> 319935 | P10: 인터넷 서비스 | Q10: 32962679 | R10: 7144.7837 | S10: 37073.462
A11: A012330 | B11: 현대모비스 | C11: 연결 | D11: 3Q | E11: =I11*Q11/100000000 -> 258934.68 | F11: =IFERROR(E11/R11,"-") -> 8.0958982 | G11: =IFERROR(E11/S11,"-") -> 0.94896483 | H11: =IFERROR(G11/F11,"-") -> 0.11721551 | I11: =IF(COUNTIF(현재가!$A:$A,$B11),VLOOKUP($B11,현재가!$A:$B,2,FALSE),VLOOKUP($B11,현재가!$D:$E,2,FALSE)) -> 266000 | J11: =VLOOKUP(A11,'EPS 성장율'!A:L,COLUMN('EPS 성장율'!L11),FALSE) -> 368460.52 | K11: =VLOOKUP($A11,'roe&pbr'!$A:$Q,COLUMN('roe&pbr'!J11),FALSE) -> 365184.54 | L11: =IFERROR(VLOOKUP($A11,야마구치요헤이!$A:$K,COLUMN(야마구치요헤이!K11),FALSE),"-") -> 349337.71 | M11: =IFERROR(VLOOKUP($A11,'RIM (개별)'!$A:$Y,COLUMN('RIM (개별)'!H15),FALSE),"-") -> 506857.82 | N11: =IFERROR(VLOOKUP($A11,'RIM (연결)'!$A:$Y,COLUMN('RIM (연결)'!H13),FALSE),"-") -> 634692.65 | O11: =IFERROR(VLOOKUP($A11,무성장가치!$A:$Q,COLUMN(무성장가치!J11),FALSE),"-") -> 213332.46 | P11: 자동차부품 | Q11: 97343863 | R11: 31983.44 | S11: 272860.14
A12: A000660 | B12: SK하이닉스 | C12: 연결 | D12: 3Q | E12: =I12*Q12/100000000 -> 684322.22 | F12: =IFERROR(E12/R12,"-") -> 31.142941 | G12: =IFERROR(E12/S12,"-") -> 3.1104659 | H12: =IFERROR(G12/F12,"-") -> 0.099877076 | I12: =IF(COUNTIF(현재가!$A:$A,$B12),VLOOKUP($B12,현재가!$A:$B,2,FALSE),VLOOKUP($B12,현재가!$D:$E,2,FALSE)) -> 94000 | J12: =VLOOKUP(A12,'EPS 성장율'!A:L,COLUMN('EPS 성장율'!L12),FALSE) -> 298580.16 | K12: =VLOOKUP($A12,'roe&pbr'!$A:$Q,COLUMN('roe&pbr'!J12),FALSE) -> 52583.444 | L12: =IFERROR(VLOOKUP($A12,야마구치요헤이!$A:$K,COLUMN(야마구치요헤이!K12),FALSE),"-") -> 451437.88 | M12: =IFERROR(VLOOKUP($A12,'RIM (개별)'!$A:$Y,COLUMN('RIM (개별)'!H16),FALSE),"-") -> 318586.29 | N12: =IFERROR(VLOOKUP($A12,'RIM (연결)'!$A:$Y,COLUMN('RIM (연결)'!H14),FALSE),"-") -> 546007.28 | O12: =IFERROR(VLOOKUP($A12,무성장가치!$A:$Q,COLUMN(무성장가치!J12),FALSE),"-") -> 414193.17 | P12: 반도체 및 관련장비 | Q12: 728002365 | R12: 21973.59 | S12: 220006.34
A13: A090430 | B13: 아모레퍼시픽 | C13: 연결 | D13: 3Q | E13: =I13*Q13/100000000 -> 106102.16 | F13: =IFERROR(E13/R13,"-") -> 16.675699 | G13: =IFERROR(E13/S13,"-") -> 2.786491 | H13: =IFERROR(G13/F13,"-") -> 0.16709891 | I13: =IF(COUNTIF(현재가!$A:$A,$B13),VLOOKUP($B13,현재가!$A:$B,2,FALSE),VLOOKUP($B13,현재가!$D:$E,2,FALSE)) -> 181500 | J13: =VLOOKUP(A13,'EPS 성장율'!A:L,COLUMN('EPS 성장율'!L13),FALSE) -> 135511.21 | K13: =VLOOKUP($A13,'roe&pbr'!$A:$Q,COLUMN('roe&pbr'!J13),FALSE) -> 85020.101 | L13: =IFERROR(VLOOKUP($A13,야마구치요헤이!$A:$K,COLUMN(야마구치요헤이!K13),FALSE),"-") -> 160319.24 | M13: =IFERROR(VLOOKUP($A13,'RIM (개별)'!$A:$Y,COLUMN('RIM (개별)'!H17),FALSE),"-") -> 96461.229 | N13: =IFERROR(VLOOKUP($A13,'RIM (연결)'!$A:$Y,COLUMN('RIM (연결)'!H15),FALSE),"-") -> 101758.87 | O13: =IFERROR(VLOOKUP($A13,무성장가치!$A:$Q,COLUMN(무성장가치!J13),FALSE),"-") -> 105387.58 | P13: 개인생활용품 | Q13: 58458490 | R13: 6362.6814 | S13: 38077.337
A14: A005490 | B14: POSCO | C14: 연결 | D14: 3Q | E14: =I14*Q14/100000000 -> 278997.87 | F14: =IFERROR(E14/R14,"-") -> 20.180326 | G14: =IFERROR(E14/S14,"-") -> 0.66951998 | H14: =IFERROR(G14/F14,"-") -> 0.033176867 | I14: =IF(COUNTIF(현재가!$A:$A,$B14),VLOOKUP($B14,현재가!$A:$B,2,FALSE),VLOOKUP($B14,현재가!$D:$E,2,FALSE)) -> 320000 | J14: =VLOOKUP(A14,'EPS 성장율'!A:L,COLUMN('EPS 성장율'!L14),FALSE) -> 41163.302 | K14: =VLOOKUP($A14,'roe&pbr'!$A:$Q,COLUMN('roe&pbr'!J14),FALSE) -> 367846.71 | L14: =IFERROR(VLOOKUP($A14,야마구치요헤이!$A:$K,COLUMN(야마구치요헤이!K14),FALSE),"-") -> 216805.28 | M14: =IFERROR(VLOOKUP($A14,'RIM (개별)'!$A:$Y,COLUMN('RIM (개별)'!H18),FALSE),"-") -> 289202.23 | N14: =IFERROR(VLOOKUP($A14,'RIM (연결)'!$A:$Y,COLUMN('RIM (연결)'!H16),FALSE),"-") -> 176345.15 | O14: =IFERROR(VLOOKUP($A14,무성장가치!$A:$Q,COLUMN(무성장가치!J14),FALSE),"-") -> 104625.42 | P14: 금속 및 광물 | Q14: 87186835 | R14: 13825.241 | S14: 416713.29
A15: A017670 | B15: SK텔레콤 | C15: 연결 | D15: 3Q | E15: =I15*Q15/100000000 -> 245870.69 | F15: =IFERROR(E15/R15,"-") -> 16.578126 | G15: =IFERROR(E15/S15,"-") -> 1.5989017 | H15: =IFERROR(G15/F15,"-") -> 0.096446464 | I15: =IF(COUNTIF(현재가!$A:$A,$B15),VLOOKUP($B15,현재가!$A:$B,2,FALSE),VLOOKUP($B15,현재가!$D:$E,2,FALSE)) -> 304500 | J15: =VLOOKUP(A15,'EPS 성장율'!A:L,COLUMN('EPS 성장율'!L15),FALSE) -> 114030.15 | K15: =VLOOKUP($A15,'roe&pbr'!$A:$Q,COLUMN('roe&pbr'!J15),FALSE) -> 253010.24 | L15: =IFERROR(VLOOKUP($A15,야마구치요헤이!$A:$K,COLUMN(야마구치요헤이!K15),FALSE),"-") -> 175102.9 | M15: =IFERROR(VLOOKUP($A15,'RIM (개별)'!$A:$Y,COLUMN('RIM (개별)'!H19),FALSE),"-") -> 179972.54 | N15: =IFERROR(VLOOKUP($A15,'RIM (연결)'!$A:$Y,COLUMN('RIM (연결)'!H17),FALSE),"-") -> 234973.92 | O15: =IFERROR(VLOOKUP($A15,무성장가치!$A:$Q,COLUMN(무성장가치!J15),FALSE),"-") -> 247840.04 | P15: 무선통신 | Q15: 80745711 | R15: 14831.03 | S15: 153774.74
A16: A051910 | B16: LG화학 | C16: 연결 | D16: 3Q | E16: =I16*Q16/100000000 -> 539325.5 | F16: =IFERROR(E16/R16,"-") -> 44.112744 | G16: =IFERROR(E16/S16,"-") -> 3.969177 | H16: =IFERROR(G16/F16,"-") -> 0.089978011 | I16: =IF(COUNTIF(현재가!$A:$A,$B16),VLOOKUP($B16,현재가!$A:$B,2,FALSE),VLOOKUP($B16,현재가!$D:$E,2,FALSE)) -> 764000 | J16: =VLOOKUP(A16,'EPS 성장율'!A:L,COLUMN('EPS 성장율'!L16),FALSE) -> 56402.424 | K16: =VLOOKUP($A16,'roe&pbr'!$A:$Q,COLUMN('roe&pbr'!J16),FALSE) -> 191060.36 | L16: =IFERROR(VLOOKUP($A16,야마구치요헤이!$A:$K,COLUMN(야마구치요헤이!K16),FALSE),"-") -> 91810.807 | M16: =IFERROR(VLOOKUP($A16,'RIM (개별)'!$A:$Y,COLUMN('RIM (개별)'!H20),FALSE),"-") -> 85697.774 | N16: =IFERROR(VLOOKUP($A16,'RIM (연결)'!$A:$Y,COLUMN('RIM (연결)'!H18),FALSE),"-") -> 135722.55 | O16: =IFERROR(VLOOKUP($A16,무성장가치!$A:$Q,COLUMN(무성장가치!J16),FALSE),"-") -> 87263.542 | P16: 화학 | Q16: 70592343 | R16: 12226.07 | S16: 135878.42
A17: A000270 | B17: 기아 | C17: 연결 | D17: 3Q | E17: =I17*Q17/100000000 -> 331992.58 | F17: =IFERROR(E17/R17,"-") -> 11.586131 | G17: =IFERROR(E17/S17,"-") -> 1.2977104 | H17: =IFERROR(G17/F17,"-") -> 0.1120055 | I17: =IF(COUNTIF(현재가!$A:$A,$B17),VLOOKUP($B17,현재가!$A:$B,2,FALSE),VLOOKUP($B17,현재가!$D:$E,2,FALSE)) -> 81900 | J17: =VLOOKUP(A17,'EPS 성장율'!A:L,COLUMN('EPS 성장율'!L17),FALSE) -> 52514.416 | K17: =VLOOKUP($A17,'roe&pbr'!$A:$Q,COLUMN('roe&pbr'!J17),FALSE) -> 79194.71 | L17: =IFERROR(VLOOKUP($A17,야마구치요헤이!$A:$K,COLUMN(야마구치요헤이!K17),FALSE),"-") -> 116031.27 | M17: =IFERROR(VLOOKUP($A17,'RIM (개별)'!$A:$Y,COLUMN('RIM (개별)'!H21),FALSE),"-") -> 94835.766 | N17: =IFERROR(VLOOKUP($A17,'RIM (연결)'!$A:$Y,COLUMN('RIM (연결)'!H19),FALSE),"-") -> 101059.49 | O17: =IFERROR(VLOOKUP($A17,무성장가치!$A:$Q,COLUMN(무성장가치!J17),FALSE),"-") -> 86302.25 | P17: 자동차 | Q17: 405363347 | R17: 28654.31 | S17: 255829.48
A18: A033780 | B18: KT&G | C18: 연결 | D18: 3Q | E18: =I18*Q18/100000000 -> 110795.05 | F18: =IFERROR(E18/R18,"-") -> 11.278526 | G18: =IFERROR(E18/S18,"-") -> 1.672197 | H18: =IFERROR(G18/F18,"-") -> 0.14826379 | I18: =IF(COUNTIF(현재가!$A:$A,$B18),VLOOKUP($B18,현재가!$A:$B,2,FALSE),VLOOKUP($B18,현재가!$D:$E,2,FALSE)) -> 80700 | J18: =VLOOKUP(A18,'EPS 성장율'!A:L,COLUMN('EPS 성장율'!L18),FALSE) -> 72247.192 | K18: =VLOOKUP($A18,'roe&pbr'!$A:$Q,COLUMN('roe&pbr'!J18),FALSE) -> 74520.646 | L18: =IFERROR(VLOOKUP($A18,야마구치요헤이!$A:$K,COLUMN(야마구치요헤이!K18),FALSE),"-") -> 275929.29 | M18: =IFERROR(VLOOKUP($A18,'RIM (개별)'!$A:$Y,COLUMN('RIM (개별)'!H22),FALSE),"-") -> 249003.41 | N18: =IFERROR(VLOOKUP($A18,'RIM (연결)'!$A:$Y,COLUMN('RIM (연결)'!H20),FALSE),"-") -> 260136.01 | O18: =IFERROR(VLOOKUP($A18,무성장가치!$A:$Q,COLUMN(무성장가치!J18),FALSE),"-") -> 182877.58 | P18: 담배 | Q18: 137292497 | R18: 9823.5395 | S18: 66257.172
... A50: A032640 | B50: LG유플러스 | C50: 연결 | D50: 3Q | E50: =I50*Q50/100000000 -> 63090.342 | F50: =IFERROR(E50/R50,"-") -> 15.226561 | G50: =IFERROR(E50/S50,"-") -> 1.3386053 | H50: =IFERROR(G50/F50,"-") -> 0.087912517 | I50: =IF(COUNTIF(현재가!$A:$A,$B50),VLOOKUP($B50,현재가!$A:$B,2,FALSE),VLOOKUP($B50,현재가!$D:$E,2,FALSE)) -> 14450 | J50: =VLOOKUP(A50,'EPS 성장율'!A:L,COLUMN('EPS 성장율'!L50),FALSE) -> 6239.6007 | K50: =VLOOKUP($A50,'roe&pbr'!$A:$Q,COLUMN('roe&pbr'!J50),FALSE) -> 10789.418 | L50: =IFERROR(VLOOKUP($A50,야마구치요헤이!$A:$K,COLUMN(야마구치요헤이!K50),FALSE),"-") -> - | M50: =IFERROR(VLOOKUP($A50,'RIM (개별)'!$A:$Y,COLUMN('RIM (개별)'!H54),FALSE),"-") -> 0 | N50: =IFERROR(VLOOKUP($A50,'RIM (연결)'!$A:$Y,COLUMN('RIM (연결)'!H52),FALSE),"-") -> 0 | O50: =IFERROR(VLOOKUP($A50,무성장가치!$A:$Q,COLUMN(무성장가치!J50),FALSE),"-") -> 0 | P50: 무선통신 | Q50: 436611361 | R50: 4143.44 | S50: 47131.4

Sheet EPS 성장율
D2: 할인율 | E2: 적용 PER | I2: 삼성전자 | K2: 주가 | L2: 주당가치 | M2: EPS 성장율 | N2: 미래주가 | O2: 기대수익율 | P2: 미래 EPS | Q2: 기간
C3: 입력 F | D3: 0.08 | E3: 12 | K3: =VLOOKUP($I2,$B:$X,COLUMN(K6)-1,FALSE) -> 71500 | L3: =VLOOKUP($I2,$B:$X,COLUMN(L6)-1,FALSE) -> 1056148.8 | M3: =VLOOKUP($I2,$B:$X,COLUMN(M6)-1,FALSE) -> 0.034393777 | N3: =VLOOKUP($I2,$B:$X,COLUMN(N6)-1,FALSE) -> 1644037.4 | O3: =VLOOKUP($I2,$B:$X,COLUMN(O6)-1,FALSE) -> 0.72504721 | P3: =VLOOKUP($I2,$B:$X,COLUMN(P6)-1,FALSE) -> 137003.12 | Q3: =VLOOKUP($I2,$B:$X,COLUMN(Q6)-1,FALSE) -> 5.75
Q4: 입력H | S4: 0.75 | T4: 1.75 | U4: 2.75 | V4: 3.75 | W4: 4.75 | X4: 5.75
A5: CODE | B5: 종목 | C5: 주재무 | D5: 실적 | E5: 시가총액 (억) | F5: PER | G5: PBR | H5: ROE | I5: PEG | J5: 괴리율 | K5: 주가 (원) | L5: 주당가치 | M5: EPS 성장율 | N5: 미래주가 | O5: 기대수익율 | P5: 미래 EPS | Q5: 기간 | R5: 2021.2Q | S5: 2020 | T5: 2019 | U5: 2018 | V5: 2017 | W5: 2016 | X5: 2015 | Y5: 업종 | Z5: 주식수
A6: A005930 | B6: 삼성전자 | C6: 연결 | D6: 3Q | E6: =K6*Z6/100000000 -> 100585.73 | F6: =VLOOKUP($A6,종합!$A:$T,COLUMN(종합!F34),FALSE) -> - | G6: =VLOOKUP($A6,종합!$A:$T,COLUMN(종합!G34),FALSE) -> - | H6: =VLOOKUP($A6,종합!$A:$T,COLUMN(종합!H34),FALSE) -> - | I6: =IFERROR(F6/(M6*100),"-") -> - | J6: =IFERROR((L6-K6)/K6,"-") -> 13.771312 | K6: =IF(COUNTIF(현재가!$A:$A,$B6),VLOOKUP($B6,현재가!$A:$B,2,FALSE),VLOOKUP($B6,현재가!$D:$E,2,FALSE)) -> 71500 | L6: =IFERROR(N6/(1+$D$3)^Q6,"-") -> 1056148.8 | M6: =IF(R6<0,"적자",IF(Q6=5.75,(R6/X6)^(1/Q6)-1,IF(Q6=4.75,(R6/W6)^(1/Q6)-1,IF(Q6=3.75,(R6/V6)^(1/Q6)-1,IF(Q6=2.75,(R6/U6)^(1/Q6)-1,IF(Q6=1.75,(R6/T6)^(1/Q6)-1,IF(Q6=0.75,(R6/S6)^(1/Q6)-1))))))) -> 0.034393777 | N6: =IFERROR(P6*$E$3,"-") -> 1644037.4 | O6: =IFERROR((N6/K6)^(1/Q6)-1,"-") -> 0.72504721 | P6: =IFERROR(R6*(1+M6)^Q6,"-") -> 137003.12 | Q6: 5.75 | R6: 112794.14 | S6: 109882.59 | T6: 135673.45 | U6: 175282.02 | V6: 136278.13 | W6: 78660.01 | X6: 92862.98 | Y6: 휴대폰 및 관련부품 | Z6: 140679337
A7: A015760 | B7: 한국전력 | C7: 연결 | D7: 3Q | E7: =K7*Z7/100000000 -> 146367.81 | F7: =VLOOKUP($A7,종합!$A:$T,COLUMN(종합!F35),FALSE) -> 1.7572433 | G7: =VLOOKUP($A7,종합!$A:$T,COLUMN(종합!G35),FALSE) -> 0.20613511 | H7: =VLOOKUP($A7,종합!$A:$T,COLUMN(종합!H35),FALSE) -> 0.11730596 | I7: =IFERROR(F7/(M7*100),"-") -> -0.037904405 | J7: =IFERROR((L7-K7)/K7,"-") -> 3.0401636 | K7: =IF(COUNTIF(현재가!$A:$A,$B7),VLOOKUP($B7,현재가!$A:$B,2,FALSE),VLOOKUP($B7,현재가!$D:$E,2,FALSE)) -> 22800 | L7: =IFERROR(N7/(1+$D$3)^Q7,"-") -> 92115.73 | M7: =IF(R7<0,"적자",IF(Q7=5.75,(R7/X7)^(1/Q7)-1,IF(Q7=4.75,(R7/W7)^(1/Q7)-1,IF(Q7=3.75,(R7/V7)^(1/Q7)-1,IF(Q7=2.75,(R7/U7)^(1/Q7)-1,IF(Q7=1.75,(R7/T7)^(1/Q7)-1,IF(Q7=0.75,(R7/S7)^(1/Q7)-1))))))) -> -0.46359872 | N7: =IFERROR(P7*$E$3,"-") -> 97589.168 | O7: =IFERROR((N7/K7)^(1/Q7)-1,"-") -> 5.9495341 | P7: =IFERROR(R7*(1+M7)^Q7,"-") -> 8132.4307 | Q7: 0.75 | R7: 12974.87 | S7: 20700.73 | T7: 4185.39 | U7: 93.48 | V7: -4932.7 | W7: -5251.46 | X7: -186.93 | Y7: 전력 | Z7: 641964077
A8: A005380 | B8: 현대차 | C8: 연결 | D8: 3Q | E8: =K8*Z8/100000000 -> 388864.59 | F8: =VLOOKUP($A8,종합!$A:$T,COLUMN(종합!F36),FALSE) -> 7.4789359 | G8: =VLOOKUP($A8,종합!$A:$T,COLUMN(종합!G36),FALSE) -> 0.70267483 | H8: =VLOOKUP($A8,종합!$A:$T,COLUMN(종합!H36),FALSE) -> 0.093953851 | I8: =IFERROR(F8/(M8*100),"-") -> - | J8: =IFERROR((L8-K8)/K8,"-") -> - | K8: =IF(COUNTIF(현재가!$A:$A,$B8),VLOOKUP($B8,현재가!$A:$B,2,FALSE),VLOOKUP($B8,현재가!$D:$E,2,FALSE)) -> 205000 | L8: =IFERROR(N8/(1+$D$3)^Q8,"-") -> - | M8: =IF(R8<0,"적자",IF(Q8=5.75,(R8/X8)^(1/Q8)-1,IF(Q8=4.75,(R8/W8)^(1/Q8)-1,IF(Q8=3.75,(R8/V8)^(1/Q8)-1,IF(Q8=2.75,(R8/U8)^(1/Q8)-1,IF(Q8=1.75,(R8/T8)^(1/Q8)-1,IF(Q8=0.75,(R8/S8)^(1/Q8)-1))))))) -> 적자 | N8: =IFERROR(P8*$E$3,"-") -> - | O8: =IFERROR((N8/K8)^(1/Q8)-1,"-") -> - | P8: =IFERROR(R8*(1+M8)^Q8,"-") -> - | Q8: 5.75 | R8: -1393.97 | S8: 17749.13 | T8: 3632.44 | U8: 361.73 | V8: 1127.16 | W8: 2367.96 | X8: 1411.12 | Y8: 자동차 | Z8: 189690043
A9: A028260 | B9: 삼성물산 | C9: 연결 | D9: 3Q | E9: =K9*Z9/100000000 -> 888162.89 | F9: =VLOOKUP($A9,종합!$A:$T,COLUMN(종합!F37),FALSE) -> -86.775022 | G9: =VLOOKUP($A9,종합!$A:$T,COLUMN(종합!G37),FALSE) -> 1.4060194 | H9: =VLOOKUP($A9,종합!$A:$T,COLUMN(종합!H37),FALSE) -> -0.016203043 | I9: =IFERROR(F9/(M9*100),"-") -> 13.365088 | J9: =IFERROR((L9-K9)/K9,"-") -> -0.87035204 | K9: =IF(COUNTIF(현재가!$A:$A,$B9),VLOOKUP($B9,현재가!$A:$B,2,FALSE),VLOOKUP($B9,현재가!$D:$E,2,FALSE)) -> 122000 | L9: =IFERROR(N9/(1+$D$3)^Q9,"-") -> 15817.051 | M9: =IF(R9<0,"적자",IF(Q9=5.75,(R9/X9)^(1/Q9)-1,IF(Q9=4.75,(R9/W9)^(1/Q9)-1,IF(Q9=3.75,(R9/V9)^(1/Q9)-1,IF(Q9=2.75,(R9/U9)^(1/Q9)-1,IF(Q9=1.75,(R9/T9)^(1/Q9)-1,IF(Q9=0.75,(R9/S9)^(1/Q9)-1))))))) -> -0.064926637 | N9: =IFERROR(P9*$E$3,"-") -> 24621.363 | O9: =IFERROR((N9/K9)^(1/Q9)-1,"-") -> -0.24295424 | P9: =IFERROR(R9*(1+M9)^Q9,"-") -> 2051.7803 | Q9: 5.75 | R9: 3018.34 | S9: 5937.28 | T9: 5766.24 | U9: 4044.59 | V9: -233.12 | W9: -95.65 | X9: 4440.23 | Y9: 복합 산업 | Z9: 728002365
A10: A035420 | B10: NAVER | C10: 연결 | D10: 3Q | E10: =K10*Z10/100000000 -> 855774.12 | F10: =VLOOKUP($A10,종합!$A:$T,COLUMN(종합!F38),FALSE) -> 17.923567 | G10: =VLOOKUP($A10,종합!$A:$T,COLUMN(종합!G38),FALSE) -> 3.4542231 | H10: =VLOOKUP($A10,종합!$A:$T,COLUMN(종합!H38),FALSE) -> 0.19271963 | I10: =IFERROR(F10/(M10*100),"-") -> 12.607879 | J10: =IFERROR((L10-K10)/K10,"-") -> -0.49615006 | K10: =IF(COUNTIF(현재가!$A:$A,$B10),VLOOKUP($B10,현재가!$A:$B,2,FALSE),VLOOKUP($B10,현재가!$D:$E,2,FALSE)) -> 388500 | L10: =IFERROR(N10/(1+$D$3)^Q10,"-") -> 195745.7 | M10: =IF(R10<0,"적자",IF(Q10=5.75,(R10/X10)^(1/Q10)-1,IF(Q10=4.75,(R10/W10)^(1/Q10)-1,IF(Q10=3.75,(R10/V10)^(1/Q10)-1,IF(Q10=2.75,(R10/U10)^(1/Q10)-1,IF(Q10=1.75,(R10/T10)^(1/Q10)-1,IF(Q10=0.75,(R10/S10)^(1/Q10)-1))))))) -> 0.014216163 | N10: =IFERROR(P10*$E$3,"-") -> 304704.47 | O10: =IFERROR((N10/K10)^(1/Q10)-1,"-") -> -0.041372126 | P10: =IFERROR(R10*(1+M10)^Q10,"-") -> 25392.039 | Q10: 5.75 | R10: 23412.46 | S10: 24883.84 | T10: 28488.1 | U10: 33121.96 | V10: 33217.87 | W10: 29686.54 | X10: 21587.21 | Y10: 인터넷 서비스 | Z10: 220276479
A11: A012330 | B11: 현대모비스 | C11: 연결 | D11: 3Q | E11: =K11*Z11/100000000 -> 87680.726 | F11: =VLOOKUP($A11,종합!$A:$T,COLUMN(종합!F39),FALSE) -> 8.0958982 | G11: =VLOOKUP($A11,종합!$A:$T,COLUMN(종합!G39),FALSE) -> 0.94896483 | H11: =VLOOKUP($A11,종합!$A:$T,COLUMN(종합!H39),FALSE) -> 0.11721551 | I11: =IFERROR(F11/(M11*100),"-") -> 0.54912798 | J11: =IFERROR((L11-K11)/K11,"-") -> 0.38518993 | K11: =IF(COUNTIF(현재가!$A:$A,$B11),VLOOKUP($B11,현재가!$A:$B,2,FALSE),VLOOKUP($B11,현재가!$D:$E,2,FALSE)) -> 266000 | L11: =IFERROR(N11/(1+$D$3)^Q11,"-") -> 368460.52 | M11: =IF(R11<0,"적자",IF(Q11=5.75,(R11/X11)^(1/Q11)-1,IF(Q11=4.75,(R11/W11)^(1/Q11)-1,IF(Q11=3.75,(R11/V11)^(1/Q11)-1,IF(Q11=2.75,(R11/U11)^(1/Q11)-1,IF(Q11=1.75,(R11/T11)^(1/Q11)-1,IF(Q11=0.75,(R11/S11)^(1/Q11)-1))))))) -> 0.1474319 | N11: =IFERROR(P11*$E$3,"-") -> 573558.28 | O11: =IFERROR((N11/K11)^(1/Q11)-1,"-") -> 0.142968 | P11: =IFERROR(R11*(1+M11)^Q11,"-") -> 47796.524 | Q11: 5.75 | R11: 21675.37 | S11: 15737.39 | T11: 13787.03 | U11: 45425.48 | V11: 11346.4 | W11: 9349.81 | X11: 9829.62 | Y11: 자동차부품 | Z11: 32962679
A12: A000660 | B12: SK하이닉스 | C12: 연결 | D12: 3Q | E12: =K12*Z12/100000000 -> 91503.231 | F12: =VLOOKUP($A12,종합!$A:$T,COLUMN(종합!F40),FALSE) -> 31.142941 | G12: =VLOOKUP($A12,종합!$A:$T,COLUMN(종합!G40),FALSE) -> 3.1104659 | H12: =VLOOKUP($A12,종합!$A:$T,COLUMN(종합!H40),FALSE) -> 0.099877076 | I12: =IFERROR(F12/(M12*100),"-") -> 10.726894 | J12: =IFERROR((L12-K12)/K12,"-") -> 2.1763847 | K12: =IF(COUNTIF(현재가!$A:$A,$B12),VLOOKUP($B12,현재가!$A:$B,2,FALSE),VLOOKUP($B12,현재가!$D:$E,2,FALSE)) -> 94000 | L12: =IFERROR(N12/(1+$D$3)^Q12,"-") -> 298580.16 | M12: =IF(R12<0,"적자",IF(Q12=5.75,(R12/X12)^(1/Q12)-1,IF(Q12=4.75,(R12/W12)^(1/Q12)-1,IF(Q12=3.75,(R12/V12)^(1/Q12)-1,IF(Q12=2.75,(R12/U12)^(1/Q12)-1,IF(Q12=1.75,(R12/T12)^(1/Q12)-1,IF(Q12=0.75,(R12/S12)^(1/Q12)-1))))))) -> 0.02903258 | N12: =IFERROR(P12*$E$3,"-") -> 464780.12 | O12: =IFERROR((N12/K12)^(1/Q12)-1,"-") -> 0.3204333 | P12: =IFERROR(R12*(1+M12)^Q12,"-") -> 38731.677 | Q12: 5.75 | R12: 32854.8 | S12: 31386.56 | T12: 35165 | U12: 35148.78 | V12: 36556.43 | W12: 31054.4 | X12: 27869.64 | Y12: 반도체 및 관련장비 | Z12: 97343863
A13: A090430 | B13: 아모레퍼시픽 | C13: 연결 | D13: 3Q | E13: =K13*Z13/100000000 -> 106102.16 | F13: =VLOOKUP($A13,종합!$A:$T,COLUMN(종합!F41),FALSE) -> 16.675699 | G13: =VLOOKUP($A13,종합!$A:$T,COLUMN(종합!G41),FALSE) -> 2.786491 | H13: =VLOOKUP($A13,종합!$A:$T,COLUMN(종합!H41),FALSE) -> 0.16709891 | I13: =IFERROR(F13/(M13*100),"-") -> 1.4038615 | J13: =IFERROR((L13-K13)/K13,"-") -> -0.25338176 | K13: =IF(COUNTIF(현재가!$A:$A,$B13),VLOOKUP($B13,현재가!$A:$B,2,FALSE),VLOOKUP($B13,현재가!$D:$E,2,FALSE)) -> 181500 | L13: =IFERROR(N13/(1+$D$3)^Q13,"-") -> 135511.21 | M13: =IF(R13<0,"적자",IF(Q13=5.75,(R13/X13)^(1/Q13)-1,IF(Q13=4.75,(R13/W13)^(1/Q13)-1,IF(Q13=3.75,(R13/V13)^(1/Q13)-1,IF(Q13=2.75,(R13/U13)^(1/Q13)-1,IF(Q13=1.75,(R13/T13)^(1/Q13)-1,IF(Q13=0.75,(R13/S13)^(1/Q13)-1))))))) -> 0.11878451 | N13: =IFERROR(P13*$E$3,"-") -> 210941.4 | O13: =IFERROR((N13/K13)^(1/Q13)-1,"-") -> 0.026488164 | P13: =IFERROR(R13*(1+M13)^Q13,"-") -> 17578.45 | Q13: 5.75 | R13: 9219.1 | S13: 9703.95 | T13: 6369.97 | U13: 4502.71 | V13: 4543.95 | W13: 5494.96 | X13: 4835 | Y13: 개인생활용품 | Z13: 58458490
A14: A005490 | B14: POSCO | C14: 연결 | D14: 3Q | E14: =K14*Z14/100000000 -> 278997.87 | F14: =VLOOKUP($A14,종합!$A:$T,COLUMN(종합!F43),FALSE) -> 20.180326 | G14: =VLOOKUP($A14,종합!$A:$T,COLUMN(종합!G43),FALSE) -> 0.66951998 | H14: =VLOOKUP($A14,종합!$A:$T,COLUMN(종합!H43),FALSE) -> 0.033176867 | I14: =IFERROR(F14/(M14*100),"-") -> -1.170161 | J14: =IFERROR((L14-K14)/K14,"-") -> -0.87136468 | K14: =IF(COUNTIF(현재가!$A:$A,$B14),VLOOKUP($B14,현재가!$A:$B,2,FALSE),VLOOKUP($B14,현재가!$D:$E,2,FALSE)) -> 320000 | L14: =IFERROR(N14/(1+$D$3)^Q14,"-") -> 41163.302 | M14: =IF(R14<0,"적자",IF(Q14=5.75,(R14/X14)^(1/Q14)-1,IF(Q14=4.75,(R14/W14)^(1/Q14)-1,IF(Q14=3.75,(R14/V14)^(1/Q14)-1,IF(Q14=2.75,(R14/U14)^(1/Q14)-1,IF(Q14=1.75,(R14/T14)^(1/Q14)-1,IF(Q14=0.75,(R14/S14)^(1/Q14)-1))))))) -> -0.17245768 | N14: =IFERROR(P14*$E$3,"-") -> 64076.208 | O14: =IFERROR((N14/K14)^(1/Q14)-1,"-") -> -0.24398592 | P14: =IFERROR(R14*(1+M14)^Q14,"-") -> 5339.684 | Q14: 5.75 | R14: 15857.03 | S14: 2071.95 | T14: 7181.12 | U14: 15786.74 | V14: 28239.13 | W14: 41842.74 | X14: 47089.94 | Y14: 금속 및 광물 | Z14: 87186835
A15: A017670 | B15: SK텔레콤 | C15: 연결 | D15: 3Q | E15: =K15*Z15/100000000 -> 245870.69 | F15: =VLOOKUP($A15,종합!$A:$T,COLUMN(종합!F45),FALSE) -> 16.578126 | G15: =VLOOKUP($A15,종합!$A:$T,COLUMN(종합!G45),FALSE) -> 1.5989017 | H15: =VLOOKUP($A15,종합!$A:$T,COLUMN(종합!H45),FALSE) -> 0.096446464 | I15: =IFERROR(F15/(M15*100),"-") -> -4.4862776 | J15: =IFERROR((L15-K15)/K15,"-") -> -0.62551674 | K15: =IF(COUNTIF(현재가!$A:$A,$B15),VLOOKUP($B15,현재가!$A:$B,2,FALSE),VLOOKUP($B15,현재가!$D:$E,2,FALSE)) -> 304500 | L15: =IFERROR(N15/(1+$D$3)^Q15,"-") -> 114030.15 | M15: =IF(R15<0,"적자",IF(Q15=5.75,(R15/X15)^(1/Q15)-1,IF(Q15=4.75,(R15/W15)^(1/Q15)-1,IF(Q15=3.75,(R15/V15)^(1/Q15)-1,IF(Q15=2.75,(R15/U15)^(1/Q15)-1,IF(Q15=1.75,(R15/T15)^(1/Q15)-1,IF(Q15=0.75,(R15/S15)^(1/Q15)-1))))))) -> -0.036952966 | N15: =IFERROR(P15*$E$3,"-") -> 177503.25 | O15: =IFERROR((N15/K15)^(1/Q15)-1,"-") -> -0.089587761 | P15: =IFERROR(R15*(1+M15)^Q15,"-") -> 14791.937 | Q15: 5.75 | R15: 18367.58 | S15: 18807.24 | T15: 22306.79 | U15: 20297.85 | V15: 14263.36 | W15: 19974.92 | X15: 22807.56 | Y15: 무선통신 | Z15: 80745711
A16: A051910 | B16: LG화학 | C16: 연결 | D16: 3Q | E16: =K16*Z16/100000000 -> 3096976 | F16: =VLOOKUP($A16,종합!$A:$T,COLUMN(종합!F46),FALSE) -> 44.112744 | G16: =VLOOKUP($A16,종합!$A:$T,COLUMN(종합!G46),FALSE) -> 3.969177 | H16: =VLOOKUP($A16,종합!$A:$T,COLUMN(종합!H46),FALSE) -> 0.089978011 | I16: =IFERROR(F16/(M16*100),"-") -> 73.427413 | J16: =IFERROR((L16-K16)/K16,"-") -> -0.92617484 | K16: =IF(COUNTIF(현재가!$A:$A,$B16),VLOOKUP($B16,현재가!$A:$B,2,FALSE),VLOOKUP($B16,현재가!$D:$E,2,FALSE)) -> 764000 | L16: =IFERROR(N16/(1+$D$3)^Q16,"-") -> 56402.424 | M16: =IF(R16<0,"적자",IF(Q16=5.75,(R16/X16)^(1/Q16)-1,IF(Q16=4.75,(R16/W16)^(1/Q16)-1,IF(Q16=3.75,(R16/V16)^(1/Q16)-1,IF(Q16=2.75,(R16/U16)^(1/Q16)-1,IF(Q16=1.75,(R16/T16)^(1/Q16)-1,IF(Q16=0.75,(R16/S16)^(1/Q16)-1))))))) -> 0.006007667 | N16: =IFERROR(P16*$E$3,"-") -> 87797.947 | O16: =IFERROR((N16/K16)^(1/Q16)-1,"-") -> -0.3135803 | P16: =IFERROR(R16*(1+M16)^Q16,"-") -> 7316.4956 | Q16: 5.75 | R16: 7068.8 | S16: 6489.49 | T16: 7384.96 | U16: 9416.39 | V16: 9537.43 | W16: 8555.74 | X16: 6829.49 | Y16: 화학 | Z16: 405363347
A17: A000270 | B17: 기아 | C17: 연결 | D17: 3Q | E17: =K17*Z17/100000000 -> 112442.56 | F17: =VLOOKUP($A17,종합!$A:$T,COLUMN(종합!F47),FALSE) -> 11.586131 | G17: =VLOOKUP($A17,종합!$A:$T,COLUMN(종합!G47),FALSE) -> 1.2977104 | H17: =VLOOKUP($A17,종합!$A:$T,COLUMN(종합!H47),FALSE) -> 0.1120055 | I17: =IFERROR(F17/(M17*100),"-") -> -13.617754 | J17: =IFERROR((L17-K17)/K17,"-") -> -0.35879835 | K17: =IF(COUNTIF(현재가!$A:$A,$B17),VLOOKUP($B17,현재가!$A:$B,2,FALSE),VLOOKUP($B17,현재가!$D:$E,2,FALSE)) -> 81900 | L17: =IFERROR(N17/(1+$D$3)^Q17,"-") -> 52514.416 | M17: =IF(R17<0,"적자",IF(Q17=5.75,(R17/X17)^(1/Q17)-1,IF(Q17=4.75,(R17/W17)^(1/Q17)-1,IF(Q17=3.75,(R17/V17)^(1/Q17)-1,IF(Q17=2.75,(R17/U17)^(1/Q17)-1,IF(Q17=1.75,(R17/T17)^(1/Q17)-1,IF(Q17=0.75,(R17/S17)^(1/Q17)-1))))))) -> -0.0085081069 | N17: =IFERROR(P17*$E$3,"-") -> 81745.74 | O17: =IFERROR((N17/K17)^(1/Q17)-1,"-") -> -0.00032782299 | P17: =IFERROR(R17*(1+M17)^Q17,"-") -> 6812.145 | Q17: 5.75 | R17: 7155.19 | S17: 7543.87 | T17: 6013.48 | U17: 4156.58 | V17: 5375.66 | W17: 5943.94 | X17: 7515.51 | Y17: 자동차 | Z17: 137292497
A18: A033780 | B18: KT&G | C18: 연결 | D18: 3Q | E18: =K18*Z18/100000000 -> 56968.021 | F18: =VLOOKUP($A18,종합!$A:$T,COLUMN(종합!F48),FALSE) -> 11.278526 | G18: =VLOOKUP($A18,종합!$A:$T,COLUMN(종합!G48),FALSE) -> 1.672197 | H18: =VLOOKUP($A18,종합!$A:$T,COLUMN(종합!H48),FALSE) -> 0.14826379 | I18: =IFERROR(F18/(M18*100),"-") -> -1.1984409 | J18: =IFERROR((L18-K18)/K18,"-") -> -0.1047436 | K18: =IF(COUNTIF(현재가!$A:$A,$B18),VLOOKUP($B18,현재가!$A:$B,2,FALSE),VLOOKUP($B18,현재가!$D:$E,2,FALSE)) -> 80700 | L18: =IFERROR(N18/(1+$D$3)^Q18,"-") -> 72247.192 | M18: =IF(R18<0,"적자",IF(Q18=5.75,(R18/X18)^(1/Q18)-1,IF(Q18=4.75,(R18/W18)^(1/Q18)-1,IF(Q18=3.75,(R18/V18)^(1/Q18)-1,IF(Q18=2.75,(R18/U18)^(1/Q18)-1,IF(Q18=1.75,(R18/T18)^(1/Q18)-1,IF(Q18=0.75,(R18/S18)^(1/Q18)-1))))))) -> -0.094109988 | N18: =IFERROR(P18*$E$3,"-") -> 112462.46 | O18: =IFERROR((N18/K18)^(1/Q18)-1,"-") -> 0.059416634 | P18: =IFERROR(R18*(1+M18)^Q18,"-") -> 9371.8713 | Q18: 5.75 | R18: 16544.07 | S18: 15601.98 | T18: 11744.57 | U18: 17130.82 | V18: 20223.09 | W18: 28929.98 | X18: 29205.08 | Y18: 담배 | Z18: 70592343
A19: A034730 | B19: SK | C19: 연결 | D19: 3Q | E19: =K19*Z19/100000000 -> 180825.96 | F19: =VLOOKUP($A19,종합!$A:$T,COLUMN(종합!F50),FALSE) -> 18.660166 | G19: =VLOOKUP($A19,종합!$A:$T,COLUMN(종합!G50),FALSE) -> 1.3998689 | H19: =VLOOKUP($A19,종합!$A:$T,COLUMN(종합!H50),FALSE) -> 0.075019102 | I19: =IFERROR(F19/(M19*100),"-") -> -0.20224074 | J19: =IFERROR((L19-K19)/K19,"-") -> -0.91169722 | K19: =IF(COUNTIF(현재가!$A:$A,$B19),VLOOKUP($B19,현재가!$A:$B,2,FALSE),VLOOKUP($B19,현재가!$D:$E,2,FALSE)) -> 257000 | L19: =IFERROR(N19/(1+$D$3)^Q19,"-") -> 22693.816 | M19: =IF(R19<0,"적자",IF(Q19=5.75,(R19/X19)^(1/Q19)-1,IF(Q19=4.75,(R19/W19)^(1/Q19)-1,IF(Q19=3.75,(R19/V19)^(1/Q19)-1,IF(Q19=2.75,(R19/U19)^(1/Q19)-1,IF(Q19=1.75,(R19/T19)^(1/Q19)-1,IF(Q19=0.75,(R19/S19)^(1/Q19)-1))))))) -> -0.92267097 | N19: =IFERROR(P19*$E$3,"-") -> 24042.263 | O19: =IFERROR((N19/K19)^(1/Q19)-1,"-") -> -0.95753254 | P19: =IFERROR(R19*(1+M19)^Q19,"-") -> 2003.5219 | Q19: 0.75 | R19: 13662.72 | S19: 93170.89 | T19: 2545.88 | U19: 4045.12 | V19: 7122.34 | W19: 8765.01 | X19: 6493.88 | Y19: 석유 및 가스 | Z19: 70360297
A20: A051900 | B20: LG생활건강 | C20: 연결 | D20: 3Q | E20: =K20*Z20/100000000 -> 216155.85 | F20: =VLOOKUP($A20,종합!$A:$T,COLUMN(종합!F51),FALSE) -> 36.330368 | G20: =VLOOKUP($A20,종합!$A:$T,COLUMN(종합!G51),FALSE) -> 8.6847275 | H20: =VLOOKUP($A20,종합!$A:$T,COLUMN(종합!H51),FALSE) -> 0.23904871 | I20: =IFERROR(F20/(M20*100),"-") -> 2.0275125 | J20: =IFERROR((L20-K20)/K20,"-") -> -0.51744829 | K20: =IF(COUNTIF(현재가!$A:$A,$B20),VLOOKUP($B20,현재가!$A:$B,2,FALSE),VLOOKUP($B20,현재가!$D:$E,2,FALSE)) -> 1384000 | L20: =IFERROR(N20/(1+$D$3)^Q20,"-") -> 667851.57 | M20: =IF(R20<0,"적자",IF(Q20=5.75,(R20/X20)^(1/Q20)-1,IF(Q20=4.75,(R20/W20)^(1/Q20)-1,IF(Q20=3.75,(R20/V20)^(1/Q20)-1,IF(Q20=2.75,(R20/U20)^(1/Q20)-1,IF(Q20=1.75,(R20/T20)^(1/Q20)-1,IF(Q20=0.75,(R20/S20)^(1/Q20)-1))))))) -> 0.1791869 | N20: =IFERROR(P20*$E$3,"-") -> 1039600.7 | O20: =IFERROR((N20/K20)^(1/Q20)-1,"-") -> -0.048545762 | P20: =IFERROR(R20*(1+M20)^Q20,"-") -> 86633.388 | Q20: 5.75 | R20: 33580.34 | S20: 25982.28 | T20: 19721.99 | U20: 20166.31 | V20: 17154.16 | W20: 14941.01 | X20: 13016.22 | Y20: 가정생활용품 | Z20: 15618197
A21: A096770 | B21: SK이노베이션 | C21: 연결 | D21: 3Q | E21: =K21*Z21/100000000 -> 229314.6 | F21: =VLOOKUP($A21,종합!$A:$T,COLUMN(종합!F52),FALSE) -> 17.298867 | G21: =VLOOKUP($A21,종합!$A:$T,COLUMN(종합!G52),FALSE) -> 1.3697576 | H21: =VLOOKUP($A21,종합!$A:$T,COLUMN(종합!H52),FALSE) -> 0.079181929 | I21: =IFERROR(F21/(M21*100),"-") -> 6.4606368 | J21: =IFERROR((L21-K21)/K21,"-") -> -0.48815614 | K21: =IF(COUNTIF(현재가!$A:$A,$B21),VLOOKUP($B21,현재가!$A:$B,2,FALSE),VLOOKUP($B21,현재가!$D:$E,2,FALSE)) -> 248000 | L21: =IFERROR(N21/(1+$D$3)^Q21,"-") -> 126937.28 | M21: =IF(R21<0,"적자",IF(Q21=5.75,(R21/X21)^(1/Q21)-1,IF(Q21=4.75,(R21/W21)^(1/Q21)-1,IF(Q21=3.75,(R21/V21)^(1/Q21)-1,IF(Q21=2.75,(R21/U21)^(1/Q21)-1,IF(Q21=1.75,(R21/T21)^(1/Q21)-1,IF(Q21=0.75,(R21/S21)^(1/Q21)-1))))))) -> 0.026775791 | N21: =IFERROR(P21*$E$3,"-") -> 197594.92 | O21: =IFERROR((N21/K21)^(1/Q21)-1,"-") -> -0.038744202 | P21: =IFERROR(R21*(1+M21)^Q21,"-") -> 16466.243 | Q21: 5.75 | R21: 14145.22 | S21: 8695.9 | T21: -6283.29 | U21: 7788.8 | V21: 12649.46 | W21: 33815.74 | X21: 12151.36 | Y21: 석유 및 가스 | Z21: 92465564
A22: A018260 | B22: 삼성에스디에스 | C22: 연결 | D22: 3Q | E22: =K22*Z22/100000000 -> 132345.38 | F22: =VLOOKUP($A22,종합!$A:$T,COLUMN(종합!F54),FALSE) -> 25.982276 | G22: =VLOOKUP($A22,종합!$A:$T,COLUMN(종합!G54),FALSE) -> 2.5684343 | H22: =VLOOKUP($A22,종합!$A:$T,COLUMN(종합!H54),FALSE) -> 0.098853325 | I22: =IFERROR(F22/(M22*100),"-") -> 1.3697405 | J22: =IFERROR((L22-K22)/K22,"-") -> -0.44746547 | K22: =IF(COUNTIF(현재가!$A:$A,$B22),VLOOKUP($B22,현재가!$A:$B,2,FALSE),VLOOKUP($B22,현재가!$D:$E,2,FALSE)) -> 160500 | L22: =IFERROR(N22/(1+$D$3)^Q22,"-") -> 88681.791 | M22: =IF(R22<0,"적자",IF(Q22=5.75,(R22/X22)^(1/Q22)-1,IF(Q22=4.75,(R22/W22)^(1/Q22)-1,IF(Q22=3.75,(R22/V22)^(1/Q22)-1,IF(Q22=2.75,(R22/U22)^(1/Q22)-1,IF(Q22=1.75,(R22/T22)^(1/Q22)-1,IF(Q22=0.75,(R22/S22)^(1/Q22)-1))))))) -> 0.18968757 | N22: =IFERROR(P22*$E$3,"-") -> 138045.12 | O22: =IFERROR((N22/K22)^(1/Q22)-1,"-") -> -0.025870494 | P22: =IFERROR(R22*(1+M22)^Q22,"-") -> 11503.76 | Q22: 5.75 | R22: 4237.41 | S22: 3158.41 | T22: 2696.63 | U22: 1976.9 | V22: 1877.65 | W22: 1800.91 | X22: 1560.85 | Y22: IT 서비스 | Z22: 82458180
A23: A068270 | B23: 셀트리온 | C23: 연결 | D23: 3Q | E23: =K23*Z23/100000000 -> 173326.27 | F23: =VLOOKUP($A23,종합!$A:$T,COLUMN(종합!F55),FALSE) -> 147.81101 | G23: =VLOOKUP($A23,종합!$A:$T,COLUMN(종합!G55),FALSE) -> 13.191926 | H23: =VLOOKUP($A23,종합!$A:$T,COLUMN(종합!H55),FALSE) -> 0.089248604 | I23: =IFERROR(F23/(M23*100),"-") -> 26.216665 | J23: =IFERROR((L23-K23)/K23,"-") -> -0.70858499 | K23: =IF(COUNTIF(현재가!$A:$A,$B23),VLOOKUP($B23,현재가!$A:$B,2,FALSE),VLOOKUP($B23,현재가!$D:$E,2,FALSE)) -> 224000 | L23: =IFERROR(N23/(1+$D$3)^Q23,"-") -> 65276.961 | M23: =IF(R23<0,"적자",IF(Q23=5.75,(R23/X23)^(1/Q23)-1,IF(Q23=4.75,(R23/W23)^(1/Q23)-1,IF(Q23=3.75,(R23/V23)^(1/Q23)-1,IF(Q23=2.75,(R23/U23)^(1/Q23)-1,IF(Q23=1.75,(R23/T23)^(1/Q23)-1,IF(Q23=0.75,(R23/S23)^(1/Q23)-1))))))) -> 0.056380554 | N23: =IFERROR(P23*$E$3,"-") -> 101612.36 | O23: =IFERROR((N23/K23)^(1/Q23)-1,"-") -> -0.12844381 | P23: =IFERROR(R23*(1+M23)^Q23,"-") -> 8467.6964 | Q23: 5.75 | R23: 6177.29 | S23: 5673.72 | T23: 5335.9 | U23: 4312.2 | V23: 5477.76 | W23: 4522.76 | X23: 4506.41 | Y23: 바이오 | Z23: 77377800
A24: A002790 | B24: 아모레G | C24: 연결 | D24: 3Q | E24: =K24*Z24/100000000 -> 58007.668 | F24: =VLOOKUP($A24,종합!$A:$T,COLUMN(종합!F56),FALSE) -> 11.740652 | G24: =VLOOKUP($A24,종합!$A:$T,COLUMN(종합!G56),FALSE) -> 1.463395 | H24: =VLOOKUP($A24,종합!$A:$T,COLUMN(종합!H56),FALSE) -> 0.12464342 | I24: =IFERROR(F24/(M24*100),"-") -> 1.8606939 | J24: =IFERROR((L24-K24)/K24,"-") -> -0.66583254 | K24: =IF(COUNTIF(현재가!$A:$A,$B24),VLOOKUP($B24,현재가!$A:$B,2,FALSE),VLOOKUP($B24,현재가!$D:$E,2,FALSE)) -> 49750 | L24: =IFERROR(N24/(1+$D$3)^Q24,"-") -> 16624.831 | M24: =IF(R24<0,"적자",IF(Q24=5.75,(R24/X24)^(1/Q24)-1,IF(Q24=4.75,(R24/W24)^(1/Q24)-1,IF(Q24=3.75,(R24/V24)^(1/Q24)-1,IF(Q24=2.75,(R24/U24)^(1/Q24)-1,IF(Q24=1.75,(R24/T24)^(1/Q24)-1,IF(Q24=0.75,(R24/S24)^(1/Q24)-1))))))) -> 0.063098242 | N24: =IFERROR(P24*$E$3,"-") -> 25878.782 | O24: =IFERROR((N24/K24)^(1/Q24)-1,"-") -> -0.10744515 | P24: =IFERROR(R24*(1+M24)^Q24,"-") -> 2156.5652 | Q24: 5.75 | R24: 1516.93 | S24: 1331.91 | T24: 1007.58 | U24: 980.61 | V24: 1673.89 | W24: 1616.05 | X24: 1067.01 | Y24: 개인생활용품 | Z24: 116598327
A25: A003550 | B25: LG | C25: 연결 | D25: 3Q | E25: =K25*Z25/100000000 -> 69844 | F25: =VLOOKUP($A25,종합!$A:$T,COLUMN(종합!F57),FALSE) -> 14.780226 | G25: =VLOOKUP($A25,종합!$A:$T,COLUMN(종합!G57),FALSE) -> 1.1768438 | H25: =VLOOKUP($A25,종합!$A:$T,COLUMN(종합!H57),FALSE) -> 0.079622852 | I25: =IFERROR(F25/(M25*100),"-") -> - | J25: =IFERROR((L25-K25)/K25,"-") -> -0.26751948 | K25: =IF(COUNTIF(현재가!$A:$A,$B25),VLOOKUP($B25,현재가!$A:$B,2,FALSE),VLOOKUP($B25,현재가!$D:$E,2,FALSE)) -> 91900 | L25: =IFERROR(N25/(1+$D$3)^Q25,"-") -> 67314.96 | M25: =IF(R25<0,"적자",IF(Q25=5.75,(R25/X25)^(1/Q25)-1,IF(Q25=4.75,(R25/W25)^(1/Q25)-1,IF(Q25=3.75,(R25/V25)^(1/Q25)-1,IF(Q25=2.75,(R25/U25)^(1/Q25)-1,IF(Q25=1.75,(R25/T25)^(1/Q25)-1,IF(Q25=0.75,(R25/S25)^(1/Q25)-1))))))) -> FALSE | N25: =IFERROR(P25*$E$3,"-") -> 67314.96 | O25: =IFERROR((N25/K25)^(1/Q25)-1,"-") -> - | P25: =IFERROR(R25*(1+M25)^Q25,"-") -> 5609.58 | R25: 5609.58 | S25: -17761.99 | T25: -23279.14 | U25: 3667.18 | V25: 13060.61 | W25: 33671.13 | X25: 54651.78 | Y25: 복합 산업 | Z25: 76000000
A26: A034220 | B26: LG디스플레이 | C26: 연결 | D26: 3Q | E26: =K26*Z26/100000000 -> 64049.01 | F26: =VLOOKUP($A26,종합!$A:$T,COLUMN(종합!F58),FALSE) -> 68.987851 | G26: =VLOOKUP($A26,종합!$A:$T,COLUMN(종합!G58),FALSE) -> 0.54086842 | H26: =VLOOKUP($A26,종합!$A:$T,COLUMN(종합!H58),FALSE) -> 0.0078400532 | I26: =IFERROR(F26/(M26*100),"-") -> -1.9428841 | J26: =IFERROR((L26-K26)/K26,"-") -> -0.99102801 | K26: =IF(COUNTIF(현재가!$A:$A,$B26),VLOOKUP($B26,현재가!$A:$B,2,FALSE),VLOOKUP($B26,현재가!$D:$E,2,FALSE)) -> 17900 | L26: =IFERROR(N26/(1+$D$3)^Q26,"-") -> 160.59867 | M26: =IF(R26<0,"적자",IF(Q26=5.75,(R26/X26)^(1/Q26)-1,IF(Q26=4.75,(R26/W26)^(1/Q26)-1,IF(Q26=3.75,(R26/V26)^(1/Q26)-1,IF(Q26=2.75,(R26/U26)^(1/Q26)-1,IF(Q26=1.75,(R26/T26)^(1/Q26)-1,IF(Q26=0.75,(R26/S26)^(1/Q26)-1))))))) -> -0.3550796 | N26: =IFERROR(P26*$E$3,"-") -> 249.9934 | O26: =IFERROR((N26/K26)^(1/Q26)-1,"-") -> -0.52422191 | P26: =IFERROR(R26*(1+M26)^Q26,"-") -> 20.832783 | Q26: 5.75 | R26: 259.47 | S26: 2701.26 | T26: 2527.19 | U26: 1190.89 | V26: 651.74 | W26: -2155.36 | X26: 3231.67 | Y26: 디스플레이 및 관련부품 | Z26: 357815700
A27: A009540 | B27: 현대중공업 | C27: 연결 | D27: 3Q | E27: =K27*Z27/100000000 -> 180322.2 | F27: =VLOOKUP($A27,종합!$A:$T,COLUMN(종합!F59),FALSE) -> 18.628854 | G27: =VLOOKUP($A27,종합!$A:$T,COLUMN(종합!G59),FALSE) -> 0.49191463 | H27: =VLOOKUP($A27,종합!$A:$T,COLUMN(종합!H59),FALSE) -> 0.026406059 | I27: =IFERROR(F27/(M27*100),"-") -> -3.1190621 | J27: =IFERROR((L27-K27)/K27,"-") -> -0.68416306 | K27: =IF(COUNTIF(현재가!$A:$A,$B27),VLOOKUP($B27,현재가!$A:$B,2,FALSE),VLOOKUP($B27,현재가!$D:$E,2,FALSE)) -> 104500 | L27: =IFERROR(N27/(1+$D$3)^Q27,"-") -> 33004.96 | M27: =IF(R27<0,"적자",IF(Q27=5.75,(R27/X27)^(1/Q27)-1,IF(Q27=4.75,(R27/W27)^(1/Q27)-1,IF(Q27=3.75,(R27/V27)^(1/Q27)-1,IF(Q27=2.75,(R27/U27)^(1/Q27)-1,IF(Q27=1.75,(R27/T27)^(1/Q27)-1,IF(Q27=0.75,(R27/S27)^(1/Q27)-1))))))) -> -0.059725819 | N27: =IFERROR(P27*$E$3,"-") -> 51376.653 | O27: =IFERROR((N27/K27)^(1/Q27)-1,"-") -> -0.11615964 | P27: =IFERROR(R27*(1+M27)^Q27,"-") -> 4281.3878 | Q27: 5.75 | R27: 6100.58 | S27: 5368.62 | T27: 4802.07 | U27: 5095.29 | V27: 5334.36 | W27: 5562.69 | X27: 8692.76 | Y27: 조선 | Z27: 172557131
A28: A011170 | B28: 롯데케미칼 | C28: 연결 | D28: 3Q | E28: =K28*Z28/100000000 -> 81746.874 | F28: =VLOOKUP($A28,종합!$A:$T,COLUMN(종합!F60),FALSE) -> 5.7237365 | G28: =VLOOKUP($A28,종합!$A:$T,COLUMN(종합!G60),FALSE) -> 0.96273302 | H28: =VLOOKUP($A28,종합!$A:$T,COLUMN(종합!H60),FALSE) -> 0.16820009 | I28: =IFERROR(F28/(M28*100),"-") -> 0.60690113 | J28: =IFERROR((L28-K28)/K28,"-") -> 1.2613826 | K28: =IF(COUNTIF(현재가!$A:$A,$B28),VLOOKUP($B28,현재가!$A:$B,2,FALSE),VLOOKUP($B28,현재가!$D:$E,2,FALSE)) -> 238500 | L28: =IFERROR(N28/(1+$D$3)^Q28,"-") -> 539339.74 | M28: =IF(R28<0,"적자",IF(Q28=5.75,(R28/X28)^(1/Q28)-1,IF(Q28=4.75,(R28/W28)^(1/Q28)-1,IF(Q28=3.75,(R28/V28)^(1/Q28)-1,IF(Q28=2.75,(R28/U28)^(1/Q28)-1,IF(Q28=1.75,(R28/T28)^(1/Q28)-1,IF(Q28=0.75,(R28/S28)^(1/Q28)-1))))))) -> 0.094310856 | N28: =IFERROR(P28*$E$3,"-") -> 839554.74 | O28: =IFERROR((N28/K28)^(1/Q28)-1,"-") -> 0.24466943 | P28: =IFERROR(R28*(1+M28)^Q28,"-") -> 69962.895 | Q28: 5.75 | R28: 41668.58 | S28: 28956.97 | T28: 4284.58 | U28: 8400.22 | V28: 9862.27 | W28: 30701.4 | X28: 24817.02 | Y28: 화학 | Z28: 34275419
A29: A010130 | B29: 고려아연 | C29: 연결 | D29: 3Q | E29: =K29*Z29/100000000 -> 597814.63 | F29: =VLOOKUP($A29,종합!$A:$T,COLUMN(종합!F61),FALSE) -> 19.662155 | G29: =VLOOKUP($A29,종합!$A:$T,COLUMN(종합!G61),FALSE) -> 1.893131 | H29: =VLOOKUP($A29,종합!$A:$T,COLUMN(종합!H61),FALSE) -> 0.09628299 | I29: =IFERROR(F29/(M29*100),"-") -> 2.5796128 | J29: =IFERROR((L29-K29)/K29,"-") -> -0.79410962 | K29: =IF(COUNTIF(현재가!$A:$A,$B29),VLOOKUP($B29,현재가!$A:$B,2,FALSE),VLOOKUP($B29,현재가!$D:$E,2,FALSE)) -> 531000 | L29: =IFERROR(N29/(1+$D$3)^Q29,"-") -> 109327.79 | M29: =IF(R29<0,"적자",IF(Q29=5.75,(R29/X29)^(1/Q29)-1,IF(Q29=4.75,(R29/W29)^(1/Q29)-1,IF(Q29=3.75,(R29/V29)^(1/Q29)-1,IF(Q29=2.75,(R29/U29)^(1/Q29)-1,IF(Q29=1.75,(R29/T29)^(1/Q29)-1,IF(Q29=0.75,(R29/S29)^(1/Q29)-1))))))) -> 0.076221339 | N29: =IFERROR(P29*$E$3,"-") -> 170183.39 | O29: =IFERROR((N29/K29)^(1/Q29)-1,"-") -> -0.17954246 | P29: =IFERROR(R29*(1+M29)^Q29,"-") -> 14181.949 | Q29: 5.75 | R29: 9296.12 | S29: 5414.21 | T29: -2468.41 | U29: 2483.94 | V29: 5018.32 | W29: 10213.79 | X29: 6093.51 | Y29: 금속 및 광물 | Z29: 112582792
A30: A035250 | B30: 강원랜드 | C30: 연결 | D30: 3Q | E30: =K30*Z30/100000000 -> 5340.21 | F30: =VLOOKUP($A30,종합!$A:$T,COLUMN(종합!F63),FALSE) -> 12.514295 | G30: =VLOOKUP($A30,종합!$A:$T,COLUMN(종합!G63),FALSE) -> 1.8936224 | H30: =VLOOKUP($A30,종합!$A:$T,COLUMN(종합!H63),FALSE) -> 0.15131674 | I30: =IFERROR(F30/(M30*100),"-") -> -9.7614151 | J30: =IFERROR((L30-K30)/K30,"-") -> 5.8304652 | K30: =IF(COUNTIF(현재가!$A:$A,$B30),VLOOKUP($B30,현재가!$A:$B,2,FALSE),VLOOKUP($B30,현재가!$D:$E,2,FALSE)) -> 28300 | L30: =IFERROR(N30/(1+$D$3)^Q30,"-") -> 193302.16 | M30: =IF(R30<0,"적자",IF(Q30=5.75,(R30/X30)^(1/Q30)-1,IF(Q30=4.75,(R30/W30)^(1/Q30)-1,IF(Q30=3.75,(R30/V30)^(1/Q30)-1,IF(Q30=2.75,(R30/U30)^(1/Q30)-1,IF(Q30=1.75,(R30/T30)^(1/Q30)-1,IF(Q30=0.75,(R30/S30)^(1/Q30)-1))))))) -> -0.012820165 | N30: =IFERROR(P30*$E$3,"-") -> 300900.78 | O30: =IFERROR((N30/K30)^(1/Q30)-1,"-") -> 0.50850079 | P30: =IFERROR(R30*(1+M30)^Q30,"-") -> 25075.065 | Q30: 5.75 | R30: 27006.2 | S30: 26993.92 | T30: 26564.58 | U30: 23745.47 | V30: 29684.78 | W30: 37341.68 | X30: 29086.06 | Y30: 호텔 및 레저 | Z30: 18870000
A31: A066570 | B31: LG전자 | C31: 연결 | D31: 3Q | E31: =K31*Z31/100000000 -> 313334.17 | F31: =VLOOKUP($A31,종합!$A:$T,COLUMN(종합!F64),FALSE) -> 78.24891 | G31: =VLOOKUP($A31,종합!$A:$T,COLUMN(종합!G64),FALSE) -> 1.7332171 | H31: =VLOOKUP($A31,종합!$A:$T,COLUMN(종합!H64),FALSE) -> 0.022150048 | I31: =IFERROR(F31/(M31*100),"-") -> -5.1422263 | J31: =IFERROR((L31-K31)/K31,"-") -> -0.9522368 | K31: =IF(COUNTIF(현재가!$A:$A,$B31),VLOOKUP($B31,현재가!$A:$B,2,FALSE),VLOOKUP($B31,현재가!$D:$E,2,FALSE)) -> 120000 | L31: =IFERROR(N31/(1+$D$3)^Q31,"-") -> 5731.5834 | M31: =IF(R31<0,"적자",IF(Q31=5.75,(R31/X31)^(1/Q31)-1,IF(Q31=4.75,(R31/W31)^(1/Q31)-1,IF(Q31=3.75,(R31/V31)^(1/Q31)-1,IF(Q31=2.75,(R31/U31)^(1/Q31)-1,IF(Q31=1.75,(R31/T31)^(1/Q31)-1,IF(Q31=0.75,(R31/S31)^(1/Q31)-1))))))) -> -0.15216932 | N31: =IFERROR(P31*$E$3,"-") -> 8921.9794 | O31: =IFERROR((N31/K31)^(1/Q31)-1,"-") -> -0.36364294 | P31: =IFERROR(R31*(1+M31)^Q31,"-") -> 743.49828 | Q31: 5.75 | R31: 1920.89 | S31: 2117.73 | T31: -4040.43 | U31: -622.1 | V31: 4006.43 | W31: 5539.97 | X31: 4962.78 | Y31: 내구소비재 | Z31: 261111808
A32: A030200 | B32: KT | C32: 연결 | D32: 3Q | E32: =K32*Z32/100000000 -> 51303.59 | F32: =VLOOKUP($A32,종합!$A:$T,COLUMN(종합!F65),FALSE) -> 16.320562 | G32: =VLOOKUP($A32,종합!$A:$T,COLUMN(종합!G65),FALSE) -> 0.72186919 | H32: =VLOOKUP($A32,종합!$A:$T,COLUMN(종합!H65),FALSE) -> 0.044230659 | I32: =IFERROR(F32/(M32*100),"-") -> -0.64873538 | J32: =IFERROR((L32-K32)/K32,"-") -> -0.93551736 | K32: =IF(COUNTIF(현재가!$A:$A,$B32),VLOOKUP($B32,현재가!$A:$B,2,FALSE),VLOOKUP($B32,현재가!$D:$E,2,FALSE)) -> 31350 | L32: =IFERROR(N32/(1+$D$3)^Q32,"-") -> 2021.5308 | M32: =IF(R32<0,"적자",IF(Q32=5.75,(R32/X32)^(1/Q32)-1,IF(Q32=4.75,(R32/W32)^(1/Q32)-1,IF(Q32=3.75,(R32/V32)^(1/Q32)-1,IF(Q32=2.75,(R32/U32)^(1/Q32)-1,IF(Q32=1.75,(R32/T32)^(1/Q32)-1,IF(Q32=0.75,(R32/S32)^(1/Q32)-1))))))) -> -0.25157502 | N32: =IFERROR(P32*$E$3,"-") -> 3146.7842 | O32: =IFERROR((N32/K32)^(1/Q32)-1,"-") -> -0.32954392 | P32: =IFERROR(R32*(1+M32)^Q32,"-") -> 262.23202 | Q32: 5.75 | R32: 1387.82 | S32: 687.89 | T32: 2208.38 | U32: 977.52 | V32: 510.87 | W32: -2809.35 | X32: 7344.81 | Y32: 무선통신 | Z32: 163647814
A33: A010950 | B33: S-Oil | C33: 연결 | D33: 3Q | E33: =K33*Z33/100000000 -> 226776.93 | F33: =VLOOKUP($A33,종합!$A:$T,COLUMN(종합!F66),FALSE) -> 11.009313 | G33: =VLOOKUP($A33,종합!$A:$T,COLUMN(종합!G66),FALSE) -> 1.91587 | H33: =VLOOKUP($A33,종합!$A:$T,COLUMN(종합!H66),FALSE) -> 0.17402267 | I33: =IFERROR(F33/(M33*100),"-") -> 4.9393619 | J33: =IFERROR((L33-K33)/K33,"-") -> -0.81331189 | K33: =IF(COUNTIF(현재가!$A:$A,$B33),VLOOKUP($B33,현재가!$A:$B,2,FALSE),VLOOKUP($B33,현재가!$D:$E,2,FALSE)) -> 106000 | L33: =IFERROR(N33/(1+$D$3)^Q33,"-") -> 19788.939 | M33: =IF(R33<0,"적자",IF(Q33=5.75,(R33/X33)^(1/Q33)-1,IF(Q33=4.75,(R33/W33)^(1/Q33)-1,IF(Q33=3.75,(R33/V33)^(1/Q33)-1,IF(Q33=2.75,(R33/U33)^(1/Q33)-1,IF(Q33=1.75,(R33/T33)^(1/Q33)-1,IF(Q33=0.75,(R33/S33)^(1/Q33)-1))))))) -> 0.022288938 | N33: =IFERROR(P33*$E$3,"-") -> 30804.141 | O33: =IFERROR((N33/K33)^(1/Q33)-1,"-") -> -0.19339403 | P33: =IFERROR(R33*(1+M33)^Q33,"-") -> 2567.0118 | Q33: 5.75 | R33: 2261.41 | S33: 2064.34 | T33: 1679.74 | U33: 1391.04 | V33: 1431.37 | W33: 1781.69 | X33: 1992.19 | Y33: 석유 및 가스 | Z33: 213940500
A34: A008930 | B34: 한미사이언스 | C34: 연결 | D34: 3Q | E34: =K34*Z34/100000000 -> 18327.699 | F34: =VLOOKUP($A34,종합!$A:$T,COLUMN(종합!F68),FALSE) -> 18.307289 | G34: =VLOOKUP($A34,종합!$A:$T,COLUMN(종합!G68),FALSE) -> 5.0687464 | H34: =VLOOKUP($A34,종합!$A:$T,COLUMN(종합!H68),FALSE) -> 0.27687039 | I34: =IFERROR(F34/(M34*100),"-") -> - | J34: =IFERROR((L34-K34)/K34,"-") -> - | K34: =IF(COUNTIF(현재가!$A:$A,$B34),VLOOKUP($B34,현재가!$A:$B,2,FALSE),VLOOKUP($B34,현재가!$D:$E,2,FALSE)) -> 58200 | L34: =IFERROR(N34/(1+$D$3)^Q34,"-") -> - | M34: =IF(R34<0,"적자",IF(Q34=5.75,(R34/X34)^(1/Q34)-1,IF(Q34=4.75,(R34/W34)^(1/Q34)-1,IF(Q34=3.75,(R34/V34)^(1/Q34)-1,IF(Q34=2.75,(R34/U34)^(1/Q34)-1,IF(Q34=1.75,(R34/T34)^(1/Q34)-1,IF(Q34=0.75,(R34/S34)^(1/Q34)-1))))))) -> 적자 | N34: =IFERROR(P34*$E$3,"-") -> - | O34: =IFERROR((N34/K34)^(1/Q34)-1,"-") -> - | P34: =IFERROR(R34*(1+M34)^Q34,"-") -> - | R34: -12226.96 | S34: -12164.39 | T34: 16723.88 | U34: 25047.92 | V34: 37194.74 | W34: 32083.57 | X34: 35626.21 | Y34: 제약 | Z34: 31490892
A35: A006400 | B35: 삼성SDI | C35: 연결 | D35: 3Q | E35: =K35*Z35/100000000 -> 523970.32 | F35: =VLOOKUP($A35,종합!$A:$T,COLUMN(종합!F69),FALSE) -> 4552.9272 | G35: =VLOOKUP($A35,종합!$A:$T,COLUMN(종합!G69),FALSE) -> 4.3364423 | H35: =VLOOKUP($A35,종합!$A:$T,COLUMN(종합!H69),FALSE) -> 0.00095245147 | I35: =IFERROR(F35/(M35*100),"-") -> 915.27377 | J35: =IFERROR((L35-K35)/K35,"-") -> -0.95062409 | K35: =IF(COUNTIF(현재가!$A:$A,$B35),VLOOKUP($B35,현재가!$A:$B,2,FALSE),VLOOKUP($B35,현재가!$D:$E,2,FALSE)) -> 686000 | L35: =IFERROR(N35/(1+$D$3)^Q35,"-") -> 33871.873 | M35: =IF(R35<0,"적자",IF(Q35=5.75,(R35/X35)^(1/Q35)-1,IF(Q35=4.75,(R35/W35)^(1/Q35)-1,IF(Q35=3.75,(R35/V35)^(1/Q35)-1,IF(Q35=2.75,(R35/U35)^(1/Q35)-1,IF(Q35=1.75,(R35/T35)^(1/Q35)-1,IF(Q35=0.75,(R35/S35)^(1/Q35)-1))))))) -> 0.049743884 | N35: =IFERROR(P35*$E$3,"-") -> 52726.12 | O35: =IFERROR((N35/K35)^(1/Q35)-1,"-") -> -0.35995724 | P35: =IFERROR(R35*(1+M35)^Q35,"-") -> 4393.8433 | Q35: 5.75 | R35: 3323.65 | S35: 4449.26 | T35: 3237.5 | U35: 3177.64 | V35: 1219.36 | W35: 2166.02 | X35: 2514.12 | Y35: 전자 장비 및 기기 | Z35: 76380513
A36: A047810 | B36: 한국항공우주 | C36: 연결 | D36: 3Q | E36: =K36*Z36/100000000 -> 39082.584 | F36: =VLOOKUP($A36,종합!$A:$T,COLUMN(종합!F70),FALSE) -> 13.141854 | G36: =VLOOKUP($A36,종합!$A:$T,COLUMN(종합!G70),FALSE) -> 2.3239213 | H36: =VLOOKUP($A36,종합!$A:$T,COLUMN(종합!H70),FALSE) -> 0.1768336 | I36: =IFERROR(F36/(M36*100),"-") -> 2.379484 | J36: =IFERROR((L36-K36)/K36,"-") -> 1.4643619 | K36: =IF(COUNTIF(현재가!$A:$A,$B36),VLOOKUP($B36,현재가!$A:$B,2,FALSE),VLOOKUP($B36,현재가!$D:$E,2,FALSE)) -> 31550 | L36: =IFERROR(N36/(1+$D$3)^Q36,"-") -> 77750.617 | M36: =IF(R36<0,"적자",IF(Q36=5.75,(R36/X36)^(1/Q36)-1,IF(Q36=4.75,(R36/W36)^(1/Q36)-1,IF(Q36=3.75,(R36/V36)^(1/Q36)-1,IF(Q36=2.75,(R36/U36)^(1/Q36)-1,IF(Q36=1.75,(R36/T36)^(1/Q36)-1,IF(Q36=0.75,(R36/S36)^(1/Q36)-1))))))) -> 0.055229847 | N36: =IFERROR(P36*$E$3,"-") -> 96076.942 | O36: =IFERROR((N36/K36)^(1/Q36)-1,"-") -> 0.49920751 | P36: =IFERROR(R36*(1+M36)^Q36,"-") -> 8006.4118 | Q36: 2.75 | R36: 6906.11 | S36: 5291.04 | T36: 5653.76 | U36: 5957.02 | V36: 1869.38 | W36: 0 | X36: 0 | Y36: 상업서비스 | Z36: 123875069
A37: A021240 | B37: 코웨이 | C37: 연결 | D37: 3Q | E37: =K37*Z37/100000000 -> 72034.104 | F37: =VLOOKUP($A37,종합!$A:$T,COLUMN(종합!F71),FALSE) -> 22.022933 | G37: =VLOOKUP($A37,종합!$A:$T,COLUMN(종합!G71),FALSE) -> 4.7030701 | H37: =VLOOKUP($A37,종합!$A:$T,COLUMN(종합!H71),FALSE) -> 0.21355331 | I37: =IFERROR(F37/(M37*100),"-") -> 1.33752 | J37: =IFERROR((L37-K37)/K37,"-") -> -0.39837216 | K37: =IF(COUNTIF(현재가!$A:$A,$B37),VLOOKUP($B37,현재가!$A:$B,2,FALSE),VLOOKUP($B37,현재가!$D:$E,2,FALSE)) -> 73900 | L37: =IFERROR(N37/(1+$D$3)^Q37,"-") -> 44460.298 | M37: =IF(R37<0,"적자",IF(Q37=5.75,(R37/X37)^(1/Q37)-1,IF(Q37=4.75,(R37/W37)^(1/Q37)-1,IF(Q37=3.75,(R37/V37)^(1/Q37)-1,IF(Q37=2.75,(R37/U37)^(1/Q37)-1,IF(Q37=1.75,(R37/T37)^(1/Q37)-1,IF(Q37=0.75,(R37/S37)^(1/Q37)-1))))))) -> 0.16465497 | N37: =IFERROR(P37*$E$3,"-") -> 69208.424 | O37: =IFERROR((N37/K37)^(1/Q37)-1,"-") -> -0.011342185 | P37: =IFERROR(R37*(1+M37)^Q37,"-") -> 5767.3687 | Q37: 5.75 | R37: 2400.73 | S37: 1852.43 | T37: 1139.87 | U37: 924.16 | V37: 760.25 | W37: 797.02 | X37: 999.33 | Y37: 내구소비재 | Z37: 97475107
A38: A004020 | B38: 현대제철 | C38: 연결 | D38: 3Q | E38: =K38*Z38/100000000 -> 60784.555 | F38: =VLOOKUP($A38,종합!$A:$T,COLUMN(종합!F73),FALSE) -> 6.2730464 | G38: =VLOOKUP($A38,종합!$A:$T,COLUMN(종합!G73),FALSE) -> 0.38196793 | H38: =VLOOKUP($A38,종합!$A:$T,COLUMN(종합!H73),FALSE) -> 0.060890339 | I38: =IFERROR(F38/(M38*100),"-") -> -0.93770245 | J38: =IFERROR((L38-K38)/K38,"-") -> -0.17470697 | K38: =IF(COUNTIF(현재가!$A:$A,$B38),VLOOKUP($B38,현재가!$A:$B,2,FALSE),VLOOKUP($B38,현재가!$D:$E,2,FALSE)) -> 45550 | L38: =IFERROR(N38/(1+$D$3)^Q38,"-") -> 37592.098 | M38: =IF(R38<0,"적자",IF(Q38=5.75,(R38/X38)^(1/Q38)-1,IF(Q38=4.75,(R38/W38)^(1/Q38)-1,IF(Q38=3.75,(R38/V38)^(1/Q38)-1,IF(Q38=2.75,(R38/U38)^(1/Q38)-1,IF(Q38=1.75,(R38/T38)^(1/Q38)-1,IF(Q38=0.75,(R38/S38)^(1/Q38)-1))))))) -> -0.066898049 | N38: =IFERROR(P38*$E$3,"-") -> 58517.148 | O38: =IFERROR((N38/K38)^(1/Q38)-1,"-") -> 0.044529788 | P38: =IFERROR(R38*(1+M38)^Q38,"-") -> 4876.429 | Q38: 5.75 | R38: 7261.22 | S38: 5865.81 | T38: 6561.67 | U38: 8102 | V38: 9334.84 | W38: 8757.48 | X38: 10812.28 | Y38: 금속 및 광물 | Z38: 133445785
A39: A128940 | B39: 한미약품 | C39: 연결 | D39: 3Q | E39: =K39*Z39/100000000 -> 97687.5 | F39: =VLOOKUP($A39,종합!$A:$T,COLUMN(종합!F74),FALSE) -> 12.345322 | G39: =VLOOKUP($A39,종합!$A:$T,COLUMN(종합!G74),FALSE) -> 3.9159601 | H39: =VLOOKUP($A39,종합!$A:$T,COLUMN(종합!H74),FALSE) -> 0.31720193 | I39: =IFERROR(F39/(M39*100),"-") -> 0.81439166 | J39: =IFERROR((L39-K39)/K39,"-") -> 0.11667177 | K39: =IF(COUNTIF(현재가!$A:$A,$B39),VLOOKUP($B39,현재가!$A:$B,2,FALSE),VLOOKUP($B39,현재가!$D:$E,2,FALSE)) -> 260500 | L39: =IFERROR(N39/(1+$D$3)^Q39,"-") -> 290893 | M39: =IF(R39<0,"적자",IF(Q39=5.75,(R39/X39)^(1/Q39)-1,IF(Q39=4.75,(R39/W39)^(1/Q39)-1,IF(Q39=3.75,(R39/V39)^(1/Q39)-1,IF(Q39=2.75,(R39/U39)^(1/Q39)-1,IF(Q39=1.75,(R39/T39)^(1/Q39)-1,IF(Q39=0.75,(R39/S39)^(1/Q39)-1))))))) -> 0.1515895 | N39: =IFERROR(P39*$E$3,"-") -> 452814.01 | O39: =IFERROR((N39/K39)^(1/Q39)-1,"-") -> 0.10092728 | P39: =IFERROR(R39*(1+M39)^Q39,"-") -> 37734.501 | Q39: 5.75 | R39: 16760.11 | S39: 10052.38 | T39: 14299.73 | U39: 12834.16 | V39: 13271.17 | W39: 9568.19 | X39: 7444.15 | Y39: 제약 | Z39: 37500000
A40: A161390 | B40: 한국타이어앤테크놀로지 | C40: 연결 | D40: 3Q | E40: =K40*Z40/100000000 -> 29396.837 | F40: =VLOOKUP($A40,종합!$A:$T,COLUMN(종합!F75),FALSE) -> 6.1901688 | G40: =VLOOKUP($A40,종합!$A:$T,COLUMN(종합!G75),FALSE) -> 0.94918298 | H40: =VLOOKUP($A40,종합!$A:$T,COLUMN(종합!H75),FALSE) -> 0.15333717 | I40: =IFERROR(F40/(M40*100),"-") -> -0.12485818 | J40: =IFERROR((L40-K40)/K40,"-") -> -0.9994823 | K40: =IF(COUNTIF(현재가!$A:$A,$B40),VLOOKUP($B40,현재가!$A:$B,2,FALSE),VLOOKUP($B40,현재가!$D:$E,2,FALSE)) -> 42750 | L40: =IFERROR(N40/(1+$D$3)^Q40,"-") -> 22.131826 | M40: =IF(R40<0,"적자",IF(Q40=5.75,(R40/X40)^(1/Q40)-1,IF(Q40=4.75,(R40/W40)^(1/Q40)-1,IF(Q40=3.75,(R40/V40)^(1/Q40)-1,IF(Q40=2.75,(R40/U40)^(1/Q40)-1,IF(Q40=1.75,(R40/T40)^(1/Q40)-1,IF(Q40=0.75,(R40/S40)^(1/Q40)-1))))))) -> -0.49577598 | N40: =IFERROR(P40*$E$3,"-") -> 34.451159 | O40: =IFERROR((N40/K40)^(1/Q40)-1,"-") -> -0.71029259 | P40: =IFERROR(R40*(1+M40)^Q40,"-") -> 2.87093 | Q40: 5.75 | R40: 147.21 | S40: 765.05 | T40: -1425.71 | U40: 2768.31 | V40: 31191.59 | W40: 6785.39 | X40: 7548.35 | Y40: 자동차부품 | Z40: 68764530
A41: A086280 | B41: 현대글로비스 | C41: 연결 | D41: 3Q | E41: =K41*Z41/100000000 -> 37717.918 | F41: =VLOOKUP($A41,종합!$A:$T,COLUMN(종합!F76),FALSE) -> 10.262465 | G41: =VLOOKUP($A41,종합!$A:$T,COLUMN(종합!G76),FALSE) -> 1.8745617 | H41: =VLOOKUP($A41,종합!$A:$T,COLUMN(종합!H76),FALSE) -> 0.18266193 | I41: =IFERROR(F41/(M41*100),"-") -> 1.0497582 | J41: =IFERROR((L41-K41)/K41,"-") -> -0.13510977 | K41: =IF(COUNTIF(현재가!$A:$A,$B41),VLOOKUP($B41,현재가!$A:$B,2,FALSE),VLOOKUP($B41,현재가!$D:$E,2,FALSE)) -> 172000 | L41: =IFERROR(N41/(1+$D$3)^Q41,"-") -> 148761.12 | M41: =IF(R41<0,"적자",IF(Q41=5.75,(R41/X41)^(1/Q41)-1,IF(Q41=4.75,(R41/W41)^(1/Q41)-1,IF(Q41=3.75,(R41/V41)^(1/Q41)-1,IF(Q41=2.75,(R41/U41)^(1/Q41)-1,IF(Q41=1.75,(R41/T41)^(1/Q41)-1,IF(Q41=0.75,(R41/S41)^(1/Q41)-1))))))) -> 0.097760274 | N41: =IFERROR(P41*$E$3,"-") -> 231566.66 | O41: =IFERROR((N41/K41)^(1/Q41)-1,"-") -> 0.053077781 | P41: =IFERROR(R41*(1+M41)^Q41,"-") -> 19297.222 | Q41: 5.75 | R41: 11286.95 | S41: 7542.22 | T41: 10487.13 | U41: 7245.48 | V41: 7120.51 | W41: 5529.04 | X41: 6601.74 | Y41: 육상운수 | Z41: 21929022
...

Sheet roe&pbr
A1: * 금융업제외
J2: 할인율 | K2: 적용기간
I3: 입력 F | J3: 0.08 | K3: 5
L4: ROE | P4: BPS
A5: CODE | B5: 종목 | C5: 주재무 | D5: 실적 | E5: 시가총액 (억) | F5: PER | G5: PBR | H5: 괴리율 | I5: 현재가 (원) | J5: 주당가치 (원) | K5: 미래BPS | L5: 3년평균 | M5: 2021.1Q | N5: 2020 | O5: 2019 | P5: 2021.1Q | Q5: 업종
A6: A005930 | B6: 삼성전자 | C6: 연결 | D6: 3Q | E6: =VLOOKUP($A6,종합!$A:$T,COLUMN(종합!E6),FALSE) -> #N/A | F6: =VLOOKUP($A6,종합!$A:$T,COLUMN(종합!F6),FALSE) -> - | G6: =VLOOKUP($A6,종합!$A:$T,COLUMN(종합!G6),FALSE) -> - | H6: =IFERROR((J6-I6)/I6,"-") -> - | I6: =VLOOKUP($A6,종합!$A:$T,COLUMN(종합!I6),FALSE) -> #N/A | J6: =IFERROR(K6/(1+$J$3)^$K$3,"-") -> 1411728.2 | K6: =IFERROR(P6*(1+L6)^$K$3,"-") -> 2074291.9 | L6: 0.12808904 | M6: 0.089157639 | N6: 0.11159024 | O6: 0.15055882 | P6: 1135410.7 | Q6: 휴대폰 및 관련부품
A7: A015760 | B7: 한국전력 | C7: 연결 | D7: 3Q | E7: =VLOOKUP($A7,종합!$A:$T,COLUMN(종합!E7),FALSE) -> 146367.81 | F7: =VLOOKUP($A7,종합!$A:$T,COLUMN(종합!F7),FALSE) -> 1.7572433 | G7: =VLOOKUP($A7,종합!$A:$T,COLUMN(종합!G7),FALSE) -> 0.20613511 | H7: =IFERROR((J7-I7)/I7,"-") -> 5.1830025 | I7: =VLOOKUP($A7,종합!$A:$T,COLUMN(종합!I7),FALSE) -> 22800 | J7: =IFERROR(K7/(1+$J$3)^$K$3,"-") -> 140972.46 | K7: =IFERROR(P7*(1+L7)^$K$3,"-") -> 207134.79 | L7: 0.13368926 | M7: 0.09955371 | N7: 0.22105109 | O7: 0.051739787 | P7: 110607.07 | Q7: 전력
A8: A005380 | B8: 현대차 | C8: 연결 | D8: 3Q | E8: =VLOOKUP($A8,종합!$A:$T,COLUMN(종합!E8),FALSE) -> 451566.78 | F8: =VLOOKUP($A8,종합!$A:$T,COLUMN(종합!F8),FALSE) -> 7.4789359 | G8: =VLOOKUP($A8,종합!$A:$T,COLUMN(종합!G8),FALSE) -> 0.70267483 | H8: =IFERROR((J8-I8)/I8,"-") -> 0.31113111 | I8: =VLOOKUP($A8,종합!$A:$T,COLUMN(종합!I8),FALSE) -> 205000 | J8: =IFERROR(K8/(1+$J$3)^$K$3,"-") -> 268781.88 | K8: =IFERROR(P8*(1+L8)^$K$3,"-") -> 394928.76 | L8: 0.11341075 | M8: 0.070076727 | N8: 0.10724211 | O8: 0.13408305 | P8: 230803.14 | Q8: 자동차
A9: A028260 | B9: 삼성물산 | C9: 연결 | D9: 3Q | E9: =VLOOKUP($A9,종합!$A:$T,COLUMN(종합!E9),FALSE) -> 231421.85 | F9: =VLOOKUP($A9,종합!$A:$T,COLUMN(종합!F9),FALSE) -> -86.775022 | G9: =VLOOKUP($A9,종합!$A:$T,COLUMN(종합!G9),FALSE) -> 1.4060194 | H9: =IFERROR((J9-I9)/I9,"-") -> -0.056595484 | I9: =VLOOKUP($A9,종합!$A:$T,COLUMN(종합!I9),FALSE) -> 122000 | J9: =IFERROR(K9/(1+$J$3)^$K$3,"-") -> 115095.35 | K9: =IFERROR(P9*(1+L9)^$K$3,"-") -> 169112.83 | L9: 0.11983907 | M9: -0.0077574718 | N9: 0.25217766 | O9: 0.098738035 | P9: 96028.13 | Q9: 복합 산업
A10: A035420 | B10: NAVER | C10: 연결 | D10: 3Q | E10: =VLOOKUP($A10,종합!$A:$T,COLUMN(종합!E10),FALSE) -> 128060.01 | F10: =VLOOKUP($A10,종합!$A:$T,COLUMN(종합!F10),FALSE) -> 17.923567 | G10: =VLOOKUP($A10,종합!$A:$T,COLUMN(종합!G10),FALSE) -> 3.4542231 | H10: =IFERROR((J10-I10)/I10,"-") -> -0.158989 | I10: =VLOOKUP($A10,종합!$A:$T,COLUMN(종합!I10),FALSE) -> 388500 | J10: =IFERROR(K10/(1+$J$3)^$K$3,"-") -> 326732.78 | K10: =IFERROR(P10*(1+L10)^$K$3,"-") -> 480077.64 | L10: 0.26918292 | M10: 0.19161091 | N10: 0.26463105 | O10: 0.27818376 | P10: 145777.46 | Q10: 인터넷 서비스
A11: A012330 | B11: 현대모비스 | C11: 연결 | D11: 3Q | E11: =VLOOKUP($A11,종합!$A:$T,COLUMN(종합!E11),FALSE) -> 258934.68 | F11: =VLOOKUP($A11,종합!$A:$T,COLUMN(종합!F11),FALSE) -> 8.0958982 | G11: =VLOOKUP($A11,종합!$A:$T,COLUMN(종합!G11),FALSE) -> 0.94896483 | H11: =IFERROR((J11-I11)/I11,"-") -> 0.3728742 | I11: =VLOOKUP($A11,종합!$A:$T,COLUMN(종합!I11),FALSE) -> 266000 | J11: =IFERROR(K11/(1+$J$3)^$K$3,"-") -> 365184.54 | K11: =IFERROR(P11*(1+L11)^$K$3,"-") -> 536575.9 | L11: 0.13584057 | M11: 0.089129043 | N11: 0.12526185 | O11: 0.15821677 | P11: 283820.84 | Q11: 자동차부품
A12: A000660 | B12: SK하이닉스 | C12: 연결 | D12: 3Q | E12: =VLOOKUP($A12,종합!$A:$T,COLUMN(종합!E12),FALSE) -> 684322.22 | F12: =VLOOKUP($A12,종합!$A:$T,COLUMN(종합!F12),FALSE) -> 31.142941 | G12: =VLOOKUP($A12,종합!$A:$T,COLUMN(종합!G12),FALSE) -> 3.1104659 | H12: =IFERROR((J12-I12)/I12,"-") -> -0.44060166 | I12: =VLOOKUP($A12,종합!$A:$T,COLUMN(종합!I12),FALSE) -> 94000 | J12: =IFERROR(K12/(1+$J$3)^$K$3,"-") -> 52583.444 | K12: =IFERROR(P12*(1+L12)^$K$3,"-") -> 77262.33 | L12: 0.1982234 | M12: 0.062062256 | N12: 0.21927917 | O12: 0.26977218 | P12: 31280.87 | Q12: 반도체 및 관련장비
A13: A090430 | B13: 아모레퍼시픽 | C13: 연결 | D13: 3Q | E13: =VLOOKUP($A13,종합!$A:$T,COLUMN(종합!E13),FALSE) -> 106102.16 | F13: =VLOOKUP($A13,종합!$A:$T,COLUMN(종합!F13),FALSE) -> 16.675699 | G13: =VLOOKUP($A13,종합!$A:$T,COLUMN(종합!G13),FALSE) -> 2.786491 | H13: =IFERROR((J13-I13)/I13,"-") -> -0.53156969 | I13: =VLOOKUP($A13,종합!$A:$T,COLUMN(종합!I13),FALSE) -> 181500 | J13: =IFERROR(K13/(1+$J$3)^$K$3,"-") -> 85020.101 | K13: =IFERROR(P13*(1+L13)^$K$3,"-") -> 124922.42 | L13: 0.17748023 | M13: 0.15889775 | N13: 0.18616853 | O13: 0.1400685 | P13: 55191.51 | Q13: 개인생활용품
A14: A005490 | B14: POSCO | C14: 연결 | D14: 3Q | E14: =VLOOKUP($A14,종합!$A:$T,COLUMN(종합!E14),FALSE) -> 278997.87 | F14: =VLOOKUP($A14,종합!$A:$T,COLUMN(종합!F15),FALSE) -> 20.180326 | G14: =VLOOKUP($A14,종합!$A:$T,COLUMN(종합!G15),FALSE) -> 0.66951998 | H14: =IFERROR((J14-I14)/I14,"-") -> 0.14952097 | I14: =VLOOKUP($A14,종합!$A:$T,COLUMN(종합!I15),FALSE) -> 320000 | J14: =IFERROR(K14/(1+$J$3)^$K$3,"-") -> 367846.71 | K14: =IFERROR(P14*(1+L14)^$K$3,"-") -> 540487.5 | L14: 0.01751391 | M14: 0.028943034 | N14: 0.0043622544 | O14: 0.01497247 | P14: 495545.89 | Q14: 금속 및 광물
A15: A017670 | B15: SK텔레콤 | C15: 연결 | D15: 3Q | E15: =VLOOKUP($A15,종합!$A:$T,COLUMN(종합!E15),FALSE) -> 245870.69 | F15: =VLOOKUP($A15,종합!$A:$T,COLUMN(종합!F17),FALSE) -> 16.578126 | G15: =VLOOKUP($A15,종합!$A:$T,COLUMN(종합!G17),FALSE) -> 1.5989017 | H15: =IFERROR((J15-I15)/I15,"-") -> -0.1690961 | I15: =VLOOKUP($A15,종합!$A:$T,COLUMN(종합!I17),FALSE) -> 304500 | J15: =IFERROR(K15/(1+$J$3)^$K$3,"-") -> 253010.24 | K15: =IFERROR(P15*(1+L15)^$K$3,"-") -> 371755.05 | L15: 0.11220516 | M15: 0.076881137 | N15: 0.1020642 | O15: 0.12884372 | P15: 218440.09 | Q15: 무선통신
A16: A051910 | B16: LG화학 | C16: 연결 | D16: 3Q | E16: =VLOOKUP($A16,종합!$A:$T,COLUMN(종합!E16),FALSE) -> 539325.5 | F16: =VLOOKUP($A16,종합!$A:$T,COLUMN(종합!F18),FALSE) -> 44.112744 | G16: =VLOOKUP($A16,종합!$A:$T,COLUMN(종합!G18),FALSE) -> 3.969177 | H16: =IFERROR((J16-I16)/I16,"-") -> -0.74992099 | I16: =VLOOKUP($A16,종합!$A:$T,COLUMN(종합!I18),FALSE) -> 764000 | J16: =IFERROR(K16/(1+$J$3)^$K$3,"-") -> 191060.36 | K16: =IFERROR(P16*(1+L16)^$K$3,"-") -> 280730.36 | L16: 0.088072332 | M16: 0.076542559 | N16: 0.09175665 | O16: 0.073128701 | P16: 184077.43 | Q16: 화학
A17: A000270 | B17: 기아 | C17: 연결 | D17: 3Q | E17: =VLOOKUP($A17,종합!$A:$T,COLUMN(종합!E17),FALSE) -> 331992.58 | F17: =VLOOKUP($A17,종합!$A:$T,COLUMN(종합!F19),FALSE) -> 11.586131 | G17: =VLOOKUP($A17,종합!$A:$T,COLUMN(종합!G19),FALSE) -> 1.2977104 | H17: =IFERROR((J17-I17)/I17,"-") -> -0.033031622 | I17: =VLOOKUP($A17,종합!$A:$T,COLUMN(종합!I19),FALSE) -> 81900 | J17: =IFERROR(K17/(1+$J$3)^$K$3,"-") -> 79194.71 | K17: =IFERROR(P17*(1+L17)^$K$3,"-") -> 116363.01 | L17: 0.12815299 | M17: 0.098246477 | N17: 0.11268874 | O17: 0.14008829 | P17: 63675.88 | Q17: 자동차
A18: A033780 | B18: KT&G | C18: 연결 | D18: 3Q | E18: =VLOOKUP($A18,종합!$A:$T,COLUMN(종합!E18),FALSE) -> 110795.05 | F18: =VLOOKUP($A18,종합!$A:$T,COLUMN(종합!F20),FALSE) -> 11.278526 | G18: =VLOOKUP($A18,종합!$A:$T,COLUMN(종합!G20),FALSE) -> 1.672197 | H18: =IFERROR((J18-I18)/I18,"-") -> -0.076571919 | I18: =VLOOKUP($A18,종합!$A:$T,COLUMN(종합!I20),FALSE) -> 80700 | J18: =IFERROR(K18/(1+$J$3)^$K$3,"-") -> 74520.646 | K18: =IFERROR(P18*(1+L18)^$K$3,"-") -> 109495.28 | L18: 0.16658913 | M18: 0.1292013 | N18: 0.17495945 | O18: 0.15141015 | P18: 50676.4 | Q18: 담배
